29m         Normal    Killing                           pod/worker-75f95467fc-c5nlk                                        Stopping container worker
29m         Warning   FailedPreStopHook                 pod/worker-75f95467fc-c5nlk                                        PreStopHook failed
26m         Warning   FailedComputeMetricsReplicas      horizontalpodautoscaler/web                                        invalid metrics (1 invalid out of 1), first error is: failed to get cpu resource metric value: failed to get cpu utilization: unable to get metrics for resource cpu: no metrics returned from resource metrics API
26m         Warning   FailedMount                       pod/worker-75f95467fc-h9ghv                                        MountVolume.SetUp failed for volume "kube-api-access-ccj6g" : token "openstudio-workload"/"openstudio-server"/[]string(nil)/3607/v1.BoundObjectReference{Kind:"Pod", APIVersion:"v1", Name:"worker-75f95467fc-h9ghv", UID:"f8f7291d-52b5-424d-8700-26a6abac0403"} expired and refresh failed: an error on the server ("<html>\r\n<head><title>502 Bad Gateway</title></head>\r\n<body>\r\n<center><h1>502 Bad Gateway</h1></center>\r\n<hr><center>nginx</center>\r\n</body>\r\n</html>") has prevented the request from succeeding (post serviceaccounts openstudio-workload)
26m         Warning   FailedMount                       pod/worker-75f95467fc-ptv8c                                        MountVolume.SetUp failed for volume "kube-api-access-cjkvb" : token "openstudio-workload"/"openstudio-server"/[]string(nil)/3607/v1.BoundObjectReference{Kind:"Pod", APIVersion:"v1", Name:"worker-75f95467fc-ptv8c", UID:"e329519d-bef5-433a-a4ee-bb86ae3cd044"} expired and refresh failed: an error on the server ("<html>\r\n<head><title>502 Bad Gateway</title></head>\r\n<body>\r\n<center><h1>502 Bad Gateway</h1></center>\r\n<hr><center>nginx</center>\r\n</body>\r\n</html>") has prevented the request from succeeding (post serviceaccounts openstudio-workload)
25m         Warning   FailedMount                       pod/worker-75f95467fc-qgt5t                                        MountVolume.SetUp failed for volume "kube-api-access-mn4lr" : failed to fetch token: an error on the server ("<html>\r\n<head><title>502 Bad Gateway</title></head>\r\n<body>\r\n<center><h1>502 Bad Gateway</h1></center>\r\n<hr><center>nginx</center>\r\n</body>\r\n</html>") has prevented the request from succeeding (post serviceaccounts openstudio-workload)
25m         Warning   FailedMount                       pod/worker-75f95467fc-7r8pb                                        MountVolume.SetUp failed for volume "kube-api-access-7r2rn" : failed to fetch token: an error on the server ("<html>\r\n<head><title>502 Bad Gateway</title></head>\r\n<body>\r\n<center><h1>502 Bad Gateway</h1></center>\r\n<hr><center>nginx</center>\r\n</body>\r\n</html>") has prevented the request from succeeding (post serviceaccounts openstudio-workload)
24m         Warning   FailedScheduling                  pod/worker-54568b5fb6-5xw8p                                        0/166 nodes are available: 160 Insufficient memory, 3 node(s) had untolerated taint {node-role.kubernetes.io/control-plane: }, 8 Insufficient cpu. preemption: 0/166 nodes are available: 163 No preemption victims found for incoming pod, 3 Preemption is not helpful for scheduling.
19m         Warning   FailedScheduling                  pod/worker-54568b5fb6-p7cv2                                        0/166 nodes are available: 160 Insufficient memory, 3 node(s) had untolerated taint {node-role.kubernetes.io/control-plane: }, 8 Insufficient cpu. preemption: 0/166 nodes are available: 163 No preemption victims found for incoming pod, 3 Preemption is not helpful for scheduling.
19m         Normal    Scheduled                         pod/worker-54568b5fb6-5xw8p                                        Successfully assigned openstudio-server/worker-54568b5fb6-5xw8p to openstudio-179d-web-tq5p9-v5jpg
19m         Normal    Pulled                            pod/worker-54568b5fb6-5xw8p                                        Container image "registry-1.docker.io/nrel/openstudio-server:3.10.0" already present on machine
19m         Normal    Started                           pod/worker-54568b5fb6-5xw8p                                        Started container worker
19m         Normal    Scheduled                         pod/worker-54568b5fb6-p7cv2                                        Successfully assigned openstudio-server/worker-54568b5fb6-p7cv2 to openstudio-179d-web-tq5p9-v5jpg
19m         Normal    ScalingReplicaSet                 deployment/worker                                                  Scaled up replica set worker-54568b5fb6 from 68 to 69
19m         Warning   FailedPreStopHook                 pod/worker-75f95467fc-g72ng                                        PreStopHook failed
19m         Normal    SuccessfulCreate                  replicaset/worker-54568b5fb6                                       Created pod: worker-54568b5fb6-2b97n
19m         Normal    SuccessfulDelete                  replicaset/worker-75f95467fc                                       Deleted pod: worker-75f95467fc-g72ng
19m         Normal    Scheduled                         pod/worker-54568b5fb6-2b97n                                        Successfully assigned openstudio-server/worker-54568b5fb6-2b97n to openstudio-179d-web-tq5p9-v5jpg
19m         Normal    ScalingReplicaSet                 deployment/worker                                                  Scaled down replica set worker-75f95467fc from 443 to 442
19m         Normal    Pulled                            pod/worker-54568b5fb6-2b97n                                        Container image "registry-1.docker.io/nrel/openstudio-server:3.10.0" already present on machine
19m         Normal    Started                           pod/worker-54568b5fb6-2b97n                                        Started container worker
19m         Normal    SuccessfulCreate                  replicaset/worker-54568b5fb6                                       Created pod: worker-54568b5fb6-qj9jj
19m         Normal    SuccessfulDelete                  replicaset/worker-75f95467fc                                       Deleted pod: worker-75f95467fc-8b492
19m         Warning   FailedPreStopHook                 pod/worker-75f95467fc-8b492                                        PreStopHook failed
19m         Warning   FailedScheduling                  pod/worker-54568b5fb6-qj9jj                                        0/167 nodes are available: 1 node(s) had untolerated taint {node.kubernetes.io/not-ready: }, 160 Insufficient memory, 3 node(s) had untolerated taint {node-role.kubernetes.io/control-plane: }, 8 Insufficient cpu. preemption: 0/167 nodes are available: 163 No preemption victims found for incoming pod, 4 Preemption is not helpful for scheduling.
19m         Warning   FailedScheduling                  pod/worker-54568b5fb6-s2z72                                        0/167 nodes are available: 1 node(s) had untolerated taint {node.kubernetes.io/not-ready: }, 160 Insufficient memory, 3 node(s) had untolerated taint {node-role.kubernetes.io/control-plane: }, 8 Insufficient cpu. preemption: 0/167 nodes are available: 163 No preemption victims found for incoming pod, 4 Preemption is not helpful for scheduling.
18m         Normal    Scheduled                         pod/worker-54568b5fb6-s2z72                                        Successfully assigned openstudio-server/worker-54568b5fb6-s2z72 to openstudio-179d-worker-9rtc4-msqdd
18m         Normal    Scheduled                         pod/worker-54568b5fb6-qj9jj                                        Successfully assigned openstudio-server/worker-54568b5fb6-qj9jj to openstudio-179d-worker-9rtc4-msqdd
18m         Warning   FailedCreatePodSandBox            pod/worker-54568b5fb6-s2z72                                        Failed to create pod sandbox: rpc error: code = Unknown desc = failed to setup network for sandbox "9f00fd15d13da1e678d76421101ddbc341bb59c8fdcaea337f6c983fac631c82": plugin type="calico" failed (add): stat /var/lib/calico/nodename: no such file or directory: check that the calico/node container is running and has mounted /var/lib/calico/
18m         Normal    TaintManagerEviction              pod/worker-54568b5fb6-s2z72                                        Cancelling deletion of Pod openstudio-server/worker-54568b5fb6-s2z72
18m         Normal    TaintManagerEviction              pod/worker-54568b5fb6-qj9jj                                        Cancelling deletion of Pod openstudio-server/worker-54568b5fb6-qj9jj
17m         Warning   FailedGetResourceMetric           horizontalpodautoscaler/web                                        failed to get cpu utilization: unable to get metrics for resource cpu: no metrics returned from resource metrics API
17m         Warning   UpdateLoadBalancerFailed          service/ingress-load-balancer                                      Error updating load balancer with new hosts [openstudio-179d-worker-9rtc4-2fbn5 openstudio-179d-worker-9rtc4-78qk8 openstudio-179d-worker-9rtc4-bpbnw openstudio-179d-worker-9rtc4-bs8zh openstudio-179d-worker-9rtc4-dnpwt openstudio-179d-worker-9rtc4-dnz4l openstudio-179d-worker-9rtc4-f2tmk openstudio-179d-worker-9rtc4-gg6xf openstudio-179d-worker-9rtc4-hdl6c openstudio-179d-worker-9rtc4-jmglf openstudio-179d-worker-9rtc4-kd9zt openstudio-179d-worker-9rtc4-llk2j openstudio-179d-worker-9rtc4-m7r54 openstudio-179d-worker-9rtc4-msqdd openstudio-179d-worker-9rtc4-nhmpl openstudio-179d-worker-9rtc4-tsmrh openstudio-179d-worker-9rtc4-wxtx7 openstudio-179d-worker-9rtc4-x5w9k openstudio-179d-worker-9rtc4-xh26n openstudio-179d-worker-9rtc4-zngnp <144 more>] [node names limited, total number of nodes: 164], error: Put "https://vs-api.hpc.nrel.gov:9876/v2.0/lbaas/pools/d4da9983-c8f4-4c98-8e90-0676796ab9f5/members": context deadline exceeded (Client.Timeout exceeded while awaiting headers)
16m         Normal    Pulled                            pod/worker-54568b5fb6-qj9jj                                        Container image "registry-1.docker.io/nrel/openstudio-server:3.10.0" already present on machine
16m         Normal    Pulled                            pod/worker-54568b5fb6-s2z72                                        Container image "registry-1.docker.io/nrel/openstudio-server:3.10.0" already present on machine
16m         Normal    Started                           pod/worker-54568b5fb6-s2z72                                        Started container worker
16m         Normal    Started                           pod/worker-54568b5fb6-qj9jj                                        Started container worker
16m         Normal    Scheduled                         pod/worker-54568b5fb6-fspwv                                        Successfully assigned openstudio-server/worker-54568b5fb6-fspwv to openstudio-179d-worker-9rtc4-msqdd
16m         Warning   FailedPreStopHook                 pod/worker-75f95467fc-26fng                                        PreStopHook failed
16m         Normal    SuccessfulCreate                  replicaset/worker-54568b5fb6                                       Created pod: worker-54568b5fb6-fspwv
16m         Normal    Scheduled                         pod/worker-54568b5fb6-mdnkv                                        Successfully assigned openstudio-server/worker-54568b5fb6-mdnkv to openstudio-179d-worker-9rtc4-msqdd
16m         Normal    ScalingReplicaSet                 deployment/worker                                                  Scaled down replica set worker-75f95467fc from 440 to 439
16m         Normal    SuccessfulDelete                  replicaset/worker-75f95467fc                                       Deleted pod: worker-75f95467fc-fd8zs
16m         Warning   FailedMount                       pod/worker-54568b5fb6-fspwv                                        MountVolume.SetUp failed for volume "kube-api-access-vz8cj" : failed to fetch token: an error on the server ("<html>\r\n<head><title>502 Bad Gateway</title></head>\r\n<body>\r\n<center><h1>502 Bad Gateway</h1></center>\r\n<hr><center>nginx</center>\r\n</body>\r\n</html>") has prevented the request from succeeding (post serviceaccounts openstudio-workload)
16m         Normal    Pulled                            pod/worker-54568b5fb6-fspwv                                        Container image "registry-1.docker.io/nrel/openstudio-server:3.10.0" already present on machine
16m         Normal    Started                           pod/worker-54568b5fb6-fspwv                                        Started container worker
16m         Normal    Started                           pod/worker-54568b5fb6-mdnkv                                        Started container worker
16m         Normal    Created                           pod/worker-54568b5fb6-mdnkv                                        Created container: worker
16m         Warning   FailedPreStopHook                 pod/worker-75f95467fc-fd8zs                                        PreStopHook failed
16m         Normal    Killing                           pod/worker-75f95467fc-fd8zs                                        Stopping container worker
15m         Normal    Killing                           pod/worker-75f95467fc-mc4bd                                        Stopping container worker
15m         Normal    Scheduled                         pod/worker-54568b5fb6-8dnk6                                        Successfully assigned openstudio-server/worker-54568b5fb6-8dnk6 to openstudio-179d-worker-9rtc4-msqdd
15m         Normal    Killing                           pod/worker-75f95467fc-kbqz8                                        Stopping container worker
15m         Normal    Scheduled                         pod/worker-54568b5fb6-h5pqv                                        Successfully assigned openstudio-server/worker-54568b5fb6-h5pqv to openstudio-179d-worker-9rtc4-msqdd
15m         Warning   FailedMount                       pod/worker-54568b5fb6-h5pqv                                        MountVolume.SetUp failed for volume "kube-api-access-shmfd" : failed to fetch token: an error on the server ("<html>\r\n<head><title>502 Bad Gateway</title></head>\r\n<body>\r\n<center><h1>502 Bad Gateway</h1></center>\r\n<hr><center>nginx</center>\r\n</body>\r\n</html>") has prevented the request from succeeding (post serviceaccounts openstudio-workload)
15m         Normal    Started                           pod/worker-54568b5fb6-h5pqv                                        Started container worker
15m         Normal    Scheduled                         pod/worker-54568b5fb6-98x2s                                        Successfully assigned openstudio-server/worker-54568b5fb6-98x2s to openstudio-179d-worker-9rtc4-msqdd
15m         Normal    Started                           pod/worker-54568b5fb6-98x2s                                        Started container worker
15m         Normal    Scheduled                         pod/worker-54568b5fb6-xh6vt                                        Successfully assigned openstudio-server/worker-54568b5fb6-xh6vt to openstudio-179d-worker-9rtc4-msqdd
15m         Normal    Pulled                            pod/worker-54568b5fb6-xh6vt                                        Container image "registry-1.docker.io/nrel/openstudio-server:3.10.0" already present on machine
15m         Normal    Killing                           pod/worker-75f95467fc-kkm9z                                        Stopping container worker
15m         Warning   FailedPreStopHook                 pod/worker-75f95467fc-kkm9z                                        PreStopHook failed
15m         Normal    Scheduled                         pod/worker-54568b5fb6-v86q7                                        Successfully assigned openstudio-server/worker-54568b5fb6-v86q7 to openstudio-179d-worker-9rtc4-msqdd
15m         Warning   FailedMount                       pod/worker-54568b5fb6-v86q7                                        MountVolume.SetUp failed for volume "kube-api-access-7mh7v" : failed to fetch token: an error on the server ("<html>\r\n<head><title>502 Bad Gateway</title></head>\r\n<body>\r\n<center><h1>502 Bad Gateway</h1></center>\r\n<hr><center>nginx</center>\r\n</body>\r\n</html>") has prevented the request from succeeding (post serviceaccounts openstudio-workload)
15m         Normal    Killing                           pod/worker-75f95467fc-pvg2k                                        Stopping container worker
15m         Normal    Scheduled                         pod/worker-54568b5fb6-zctw5                                        Successfully assigned openstudio-server/worker-54568b5fb6-zctw5 to openstudio-179d-worker-9rtc4-msqdd
15m         Normal    Started                           pod/worker-54568b5fb6-zctw5                                        Started container worker
15m         Normal    Created                           pod/worker-54568b5fb6-zctw5                                        Created container: worker
15m         Warning   FailedPreStopHook                 pod/worker-75f95467fc-pvg2k                                        PreStopHook failed
15m         Normal    Created                           pod/worker-54568b5fb6-v86q7                                        Created container: worker
15m         Normal    Pulled                            pod/worker-54568b5fb6-v86q7                                        Container image "registry-1.docker.io/nrel/openstudio-server:3.10.0" already present on machine
15m         Normal    Scheduled                         pod/worker-54568b5fb6-k49dn                                        Successfully assigned openstudio-server/worker-54568b5fb6-k49dn to openstudio-179d-worker-9rtc4-msqdd
15m         Normal    Pulled                            pod/worker-54568b5fb6-k49dn                                        Container image "registry-1.docker.io/nrel/openstudio-server:3.10.0" already present on machine
15m         Normal    Killing                           pod/worker-75f95467fc-m266v                                        Stopping container worker
15m         Normal    Created                           pod/worker-54568b5fb6-k49dn                                        Created container: worker
15m         Normal    Started                           pod/worker-54568b5fb6-k49dn                                        Started container worker
15m         Warning   FailedScheduling                  pod/worker-54568b5fb6-qscng                                        0/168 nodes are available: 1 node(s) had untolerated taint {node.kubernetes.io/not-ready: }, 161 Insufficient memory, 3 node(s) had untolerated taint {node-role.kubernetes.io/control-plane: }, 8 Insufficient cpu. preemption: 0/168 nodes are available: 164 No preemption victims found for incoming pod, 4 Preemption is not helpful for scheduling.
15m         Warning   FailedPreStopHook                 pod/worker-75f95467fc-m266v                                        PreStopHook failed
15m         Normal    Killing                           pod/worker-75f95467fc-b2pj4                                        Stopping container worker
14m         Warning   FailedScheduling                  pod/worker-54568b5fb6-bcslp                                        0/168 nodes are available: 1 node(s) had untolerated taint {node.kubernetes.io/not-ready: }, 161 Insufficient memory, 3 node(s) had untolerated taint {node-role.kubernetes.io/control-plane: }, 8 Insufficient cpu. preemption: 0/168 nodes are available: 164 No preemption victims found for incoming pod, 4 Preemption is not helpful for scheduling.
14m         Normal    Scheduled                         pod/worker-54568b5fb6-qscng                                        Successfully assigned openstudio-server/worker-54568b5fb6-qscng to openstudio-179d-web-tq5p9-w952x
14m         Warning   FailedMount                       pod/worker-54568b5fb6-qscng                                        MountVolume.SetUp failed for volume "kube-api-access-9d9h6" : failed to fetch token: an error on the server ("<html>\r\n<head><title>502 Bad Gateway</title></head>\r\n<body>\r\n<center><h1>502 Bad Gateway</h1></center>\r\n<hr><center>nginx</center>\r\n</body>\r\n</html>") has prevented the request from succeeding (post serviceaccounts openstudio-workload)
14m         Warning   FailedScheduling                  pod/worker-54568b5fb6-bcslp                                        0/168 nodes are available: 1 node(s) had untolerated taint {node.kubernetes.io/not-ready: }, 1 node(s) had untolerated taint {node.kubernetes.io/unreachable: }, 160 Insufficient memory, 3 node(s) had untolerated taint {node-role.kubernetes.io/control-plane: }, 8 Insufficient cpu. preemption: 0/168 nodes are available: 163 No preemption victims found for incoming pod, 5 Preemption is not helpful for scheduling.
14m         Warning   NodeNotReady                      pod/worker-75f95467fc-txd2v                                        Node is not ready
14m         Warning   NodeNotReady                      pod/worker-75f95467fc-vljbn                                        Node is not ready
14m         Warning   NodeNotReady                      pod/worker-75f95467fc-t4sd6                                        Node is not ready
14m         Warning   NodeNotReady                      pod/worker-75f95467fc-pgq6k                                        Node is not ready
14m         Warning   NodeNotReady                      pod/worker-75f95467fc-dv8jx                                        Node is not ready
14m         Normal    Pulled                            pod/worker-54568b5fb6-qscng                                        Container image "registry-1.docker.io/nrel/openstudio-server:3.10.0" already present on machine
14m         Warning   NodeNotReady                      pod/worker-75f95467fc-z297z                                        Node is not ready
14m         Warning   NodeNotReady                      pod/worker-75f95467fc-9rrvn                                        Node is not ready
14m         Warning   NodeNotReady                      pod/worker-75f95467fc-gv4sz                                        Node is not ready
14m         Warning   NodeNotReady                      pod/worker-75f95467fc-pf6dt                                        Node is not ready
14m         Normal    Scheduled                         pod/worker-54568b5fb6-bcslp                                        Successfully assigned openstudio-server/worker-54568b5fb6-bcslp to openstudio-179d-worker-9rtc4-vkfwc
13m         Normal    TaintManagerEviction              pod/worker-75f95467fc-pf6dt                                        Cancelling deletion of Pod openstudio-server/worker-75f95467fc-pf6dt
13m         Normal    TaintManagerEviction              pod/worker-75f95467fc-txd2v                                        Cancelling deletion of Pod openstudio-server/worker-75f95467fc-txd2v
13m         Normal    TaintManagerEviction              pod/worker-75f95467fc-dv8jx                                        Cancelling deletion of Pod openstudio-server/worker-75f95467fc-dv8jx
13m         Normal    TaintManagerEviction              pod/worker-75f95467fc-9rrvn                                        Cancelling deletion of Pod openstudio-server/worker-75f95467fc-9rrvn
13m         Normal    TaintManagerEviction              pod/worker-75f95467fc-t4sd6                                        Cancelling deletion of Pod openstudio-server/worker-75f95467fc-t4sd6
13m         Normal    TaintManagerEviction              pod/worker-75f95467fc-pgq6k                                        Cancelling deletion of Pod openstudio-server/worker-75f95467fc-pgq6k
13m         Normal    TaintManagerEviction              pod/worker-75f95467fc-z297z                                        Cancelling deletion of Pod openstudio-server/worker-75f95467fc-z297z
13m         Normal    TaintManagerEviction              pod/worker-75f95467fc-vljbn                                        Cancelling deletion of Pod openstudio-server/worker-75f95467fc-vljbn
13m         Normal    TaintManagerEviction              pod/worker-75f95467fc-gv4sz                                        Cancelling deletion of Pod openstudio-server/worker-75f95467fc-gv4sz
13m         Warning   FailedMount                       pod/worker-75f95467fc-4wkg8                                        MountVolume.SetUp failed for volume "kube-api-access-fm8xw" : failed to fetch token: an error on the server ("<html>\r\n<head><title>502 Bad Gateway</title></head>\r\n<body>\r\n<center><h1>502 Bad Gateway</h1></center>\r\n<hr><center>nginx</center>\r\n</body>\r\n</html>") has prevented the request from succeeding (post serviceaccounts openstudio-workload)
13m         Warning   FailedMount                       pod/worker-54568b5fb6-bcslp                                        MountVolume.SetUp failed for volume "kube-api-access-vrmn6" : failed to fetch token: an error on the server ("<html>\r\n<head><title>502 Bad Gateway</title></head>\r\n<body>\r\n<center><h1>502 Bad Gateway</h1></center>\r\n<hr><center>nginx</center>\r\n</body>\r\n</html>") has prevented the request from succeeding (post serviceaccounts openstudio-workload)
13m         Normal    Created                           pod/worker-54568b5fb6-bcslp                                        Created container: worker
13m         Normal    Killing                           pod/worker-75f95467fc-pgq6k                                        Stopping container worker
13m         Normal    Started                           pod/worker-54568b5fb6-bcslp                                        Started container worker
13m         Normal    Pulled                            pod/worker-54568b5fb6-bcslp                                        Container image "registry-1.docker.io/nrel/openstudio-server:3.10.0" already present on machine
13m         Normal    Scheduled                         pod/worker-54568b5fb6-rnhxg                                        Successfully assigned openstudio-server/worker-54568b5fb6-rnhxg to openstudio-179d-worker-9rtc4-h457w
12m         Warning   FailedMount                       pod/worker-75f95467fc-b6p9d                                        MountVolume.SetUp failed for volume "kube-api-access-jw95m" : failed to fetch token: an error on the server ("<html>\r\n<head><title>502 Bad Gateway</title></head>\r\n<body>\r\n<center><h1>502 Bad Gateway</h1></center>\r\n<hr><center>nginx</center>\r\n</body>\r\n</html>") has prevented the request from succeeding (post serviceaccounts openstudio-workload)
12m         Normal    SuccessfulCreate                  replicaset/worker-54568b5fb6                                       (combined from similar events): Created pod: worker-54568b5fb6-dw25f
12m         Normal    Scheduled                         pod/worker-54568b5fb6-dw25f                                        Successfully assigned openstudio-server/worker-54568b5fb6-dw25f to openstudio-179d-worker-9rtc4-zfv7b
12m         Warning   FailedMount                       pod/worker-54568b5fb6-rnhxg                                        MountVolume.SetUp failed for volume "kube-api-access-zb5sf" : failed to fetch token: an error on the server ("<html>\r\n<head><title>502 Bad Gateway</title></head>\r\n<body>\r\n<center><h1>502 Bad Gateway</h1></center>\r\n<hr><center>nginx</center>\r\n</body>\r\n</html>") has prevented the request from succeeding (post serviceaccounts openstudio-workload)
12m         Warning   FailedMount                       pod/worker-54568b5fb6-dw25f                                        MountVolume.SetUp failed for volume "kube-api-access-l47qk" : failed to fetch token: an error on the server ("<html>\r\n<head><title>502 Bad Gateway</title></head>\r\n<body>\r\n<center><h1>502 Bad Gateway</h1></center>\r\n<hr><center>nginx</center>\r\n</body>\r\n</html>") has prevented the request from succeeding (post serviceaccounts openstudio-workload)
12m         Normal    Pulled                            pod/worker-54568b5fb6-dw25f                                        Container image "registry-1.docker.io/nrel/openstudio-server:3.10.0" already present on machine
12m         Normal    Created                           pod/worker-54568b5fb6-dw25f                                        Created container: worker
11m         Normal    Started                           pod/worker-54568b5fb6-rnhxg                                        Started container worker
11m         Normal    Scheduled                         pod/worker-54568b5fb6-mrqft                                        Successfully assigned openstudio-server/worker-54568b5fb6-mrqft to openstudio-179d-worker-9rtc4-zc87d
11m         Normal    SuccessfulDelete                  replicaset/worker-75f95467fc                                       (combined from similar events): Deleted pod: worker-75f95467fc-mtqz7
9m50s       Warning   UpdateLoadBalancerFailed          service/ingress-load-balancer                                      Error updating load balancer with new hosts [openstudio-179d-worker-9rtc4-2fbn5 openstudio-179d-worker-9rtc4-78qk8 openstudio-179d-worker-9rtc4-bpbnw openstudio-179d-worker-9rtc4-bs8zh openstudio-179d-worker-9rtc4-dnpwt openstudio-179d-worker-9rtc4-dnz4l openstudio-179d-worker-9rtc4-f2tmk openstudio-179d-worker-9rtc4-gg6xf openstudio-179d-worker-9rtc4-hdl6c openstudio-179d-worker-9rtc4-jmglf openstudio-179d-worker-9rtc4-kd9zt openstudio-179d-worker-9rtc4-llk2j openstudio-179d-worker-9rtc4-m7r54 openstudio-179d-worker-9rtc4-msqdd openstudio-179d-worker-9rtc4-nhmpl openstudio-179d-worker-9rtc4-pv7qr openstudio-179d-worker-9rtc4-rj7mk openstudio-179d-worker-9rtc4-tsmrh openstudio-179d-worker-9rtc4-wxtx7 openstudio-179d-worker-9rtc4-zngnp <144 more>] [node names limited, total number of nodes: 164], error: Put "https://vs-api.hpc.nrel.gov:9876/v2.0/lbaas/pools/d4da9983-c8f4-4c98-8e90-0676796ab9f5/members": context deadline exceeded (Client.Timeout exceeded while awaiting headers)
8m13s       Warning   FailedPreStopHook                 pod/worker-75f95467fc-qz4ww                                        PreStopHook failed
8m13s       Normal    SuccessfulRescale                 horizontalpodautoscaler/worker                                     New size: 460; reason: All metrics below target
8m13s       Normal    Killing                           pod/worker-75f95467fc-2p8pc                                        Stopping container worker
8m13s       Warning   FailedPreStopHook                 pod/worker-75f95467fc-gxsqc                                        PreStopHook failed
8m13s       Normal    Killing                           pod/worker-75f95467fc-h6zl5                                        Stopping container worker
8m13s       Normal    Killing                           pod/worker-75f95467fc-c6wp5                                        Stopping container worker
8m13s       Warning   FailedPreStopHook                 pod/worker-75f95467fc-t5m65                                        PreStopHook failed
8m13s       Normal    Killing                           pod/worker-75f95467fc-rtm4v                                        Stopping container worker
8m13s       Normal    Killing                           pod/worker-75f95467fc-599bk                                        Stopping container worker
8m13s       Warning   FailedPreStopHook                 pod/worker-75f95467fc-dvjxw                                        PreStopHook failed
8m13s       Warning   FailedPreStopHook                 pod/worker-75f95467fc-dk7fk                                        PreStopHook failed
8m13s       Warning   FailedPreStopHook                 pod/worker-75f95467fc-h6zl5                                        PreStopHook failed
8m13s       Warning   FailedPreStopHook                 pod/worker-75f95467fc-rtm4v                                        PreStopHook failed
8m13s       Normal    Killing                           pod/worker-75f95467fc-lcrr4                                        Stopping container worker
8m12s       Normal    Killing                           pod/worker-75f95467fc-qmpbp                                        Stopping container worker
8m12s       Normal    Killing                           pod/worker-75f95467fc-sl8bg                                        Stopping container worker
8m12s       Normal    Killing                           pod/worker-75f95467fc-kzl5s                                        Stopping container worker
8m12s       Warning   FailedPreStopHook                 pod/worker-75f95467fc-kzl5s                                        PreStopHook failed
8m12s       Normal    Killing                           pod/worker-75f95467fc-bqfl6                                        Stopping container worker
8m12s       Warning   FailedPreStopHook                 pod/worker-75f95467fc-qmzq9                                        PreStopHook failed
8m7s        Normal    Killing                           pod/worker-54568b5fb6-8dnk6                                        Stopping container worker
8m7s        Warning   FailedPreStopHook                 pod/worker-54568b5fb6-fspwv                                        PreStopHook failed
8m7s        Normal    Killing                           pod/worker-54568b5fb6-xh6vt                                        Stopping container worker
8m7s        Warning   FailedPreStopHook                 pod/worker-54568b5fb6-v86q7                                        PreStopHook failed
8m7s        Normal    Killing                           pod/worker-54568b5fb6-fspwv                                        Stopping container worker
8m4s        Warning   FailedPreStopHook                 pod/worker-75f95467fc-lsxrv                                        PreStopHook failed
8m4s        Warning   FailedPreStopHook                 pod/worker-75f95467fc-lcnkr                                        PreStopHook failed
8m4s        Warning   FailedPreStopHook                 pod/worker-75f95467fc-64nvx                                        PreStopHook failed
8m4s        Normal    Killing                           pod/worker-75f95467fc-lsxrv                                        Stopping container worker
8m4s        Normal    Killing                           pod/worker-75f95467fc-lcnkr                                        Stopping container worker
8m4s        Normal    Killing                           pod/worker-75f95467fc-qz82v                                        Stopping container worker
8m4s        Warning   FailedPreStopHook                 pod/worker-75f95467fc-qz82v                                        PreStopHook failed
8m4s        Normal    Killing                           pod/worker-75f95467fc-64nvx                                        Stopping container worker
8m4s        Warning   FailedPreStopHook                 pod/worker-75f95467fc-x8xd2                                        PreStopHook failed
7m58s       Normal    Scheduled                         pod/worker-75f95467fc-zl8ns                                        Successfully assigned openstudio-server/worker-75f95467fc-zl8ns to openstudio-179d-worker-9rtc4-km2jz
7m58s       Normal    SuccessfulRescale                 horizontalpodautoscaler/worker                                     New size: 461; reason: external metric s0-redis-resque-queue-simulations(&LabelSelector{MatchLabels:map[string]string{scaledobject.keda.sh/name: worker,},MatchExpressions:[]LabelSelectorRequirement{},}) above target
7m57s       Warning   FailedMount                       pod/worker-75f95467fc-zl8ns                                        MountVolume.SetUp failed for volume "kube-api-access-vx9br" : failed to fetch token: an error on the server ("<html>\r\n<head><title>502 Bad Gateway</title></head>\r\n<body>\r\n<center><h1>502 Bad Gateway</h1></center>\r\n<hr><center>nginx</center>\r\n</body>\r\n</html>") has prevented the request from succeeding (post serviceaccounts openstudio-workload)
7m56s       Normal    Killing                           pod/worker-75f95467fc-4wkg8                                        Stopping container worker
7m56s       Warning   FailedPreStopHook                 pod/worker-75f95467fc-hgc66                                        PreStopHook failed
7m54s       Normal    Created                           pod/worker-75f95467fc-zl8ns                                        Created container: worker
7m54s       Normal    Started                           pod/worker-75f95467fc-zl8ns                                        Started container worker
7m43s       Normal    Scheduled                         pod/worker-75f95467fc-f7xs9                                        Successfully assigned openstudio-server/worker-75f95467fc-f7xs9 to openstudio-179d-worker-9rtc4-vkfwc
7m43s       Normal    SuccessfulRescale                 horizontalpodautoscaler/worker                                     New size: 462; reason: external metric s0-redis-resque-queue-simulations(&LabelSelector{MatchLabels:map[string]string{scaledobject.keda.sh/name: worker,},MatchExpressions:[]LabelSelectorRequirement{},}) above target
7m28s       Normal    SuccessfulRescale                 horizontalpodautoscaler/worker                                     New size: 463; reason: external metric s0-redis-resque-queue-simulations(&LabelSelector{MatchLabels:map[string]string{scaledobject.keda.sh/name: worker,},MatchExpressions:[]LabelSelectorRequirement{},}) above target
7m28s       Normal    Scheduled                         pod/worker-75f95467fc-6rgzz                                        Successfully assigned openstudio-server/worker-75f95467fc-6rgzz to openstudio-179d-worker-9rtc4-zfv7b
7m28s       Normal    SuccessfulCreate                  replicaset/worker-75f95467fc                                       Created pod: worker-75f95467fc-6rgzz
7m24s       Warning   FailedMount                       pod/worker-75f95467fc-6rgzz                                        MountVolume.SetUp failed for volume "kube-api-access-ll9w7" : failed to fetch token: an error on the server ("<html>\r\n<head><title>502 Bad Gateway</title></head>\r\n<body>\r\n<center><h1>502 Bad Gateway</h1></center>\r\n<hr><center>nginx</center>\r\n</body>\r\n</html>") has prevented the request from succeeding (post serviceaccounts openstudio-workload)
7m19s       Normal    Started                           pod/worker-75f95467fc-6rgzz                                        Started container worker
7m19s       Normal    Pulled                            pod/worker-75f95467fc-6rgzz                                        Container image "registry-1.docker.io/nrel/openstudio-server:3.10.0" already present on machine
7m19s       Normal    Created                           pod/worker-75f95467fc-6rgzz                                        Created container: worker
7m13s       Normal    SuccessfulRescale                 horizontalpodautoscaler/worker                                     New size: 464; reason: external metric s0-redis-resque-queue-simulations(&LabelSelector{MatchLabels:map[string]string{scaledobject.keda.sh/name: worker,},MatchExpressions:[]LabelSelectorRequirement{},}) above target
7m13s       Normal    Scheduled                         pod/worker-75f95467fc-b4h9s                                        Successfully assigned openstudio-server/worker-75f95467fc-b4h9s to openstudio-179d-worker-9rtc4-zc87d
6m58s       Normal    SuccessfulRescale                 horizontalpodautoscaler/worker                                     New size: 465; reason: external metric s0-redis-resque-queue-simulations(&LabelSelector{MatchLabels:map[string]string{scaledobject.keda.sh/name: worker,},MatchExpressions:[]LabelSelectorRequirement{},}) above target
6m58s       Normal    Scheduled                         pod/worker-75f95467fc-74hsk                                        Successfully assigned openstudio-server/worker-75f95467fc-74hsk to openstudio-179d-worker-9rtc4-h457w
6m57s       Normal    Created                           pod/worker-75f95467fc-74hsk                                        Created container: worker
6m43s       Normal    SuccessfulRescale                 horizontalpodautoscaler/worker                                     New size: 466; reason: external metric s0-redis-resque-queue-simulations(&LabelSelector{MatchLabels:map[string]string{scaledobject.keda.sh/name: worker,},MatchExpressions:[]LabelSelectorRequirement{},}) above target
6m43s       Normal    Scheduled                         pod/worker-75f95467fc-cg8pc                                        Successfully assigned openstudio-server/worker-75f95467fc-cg8pc to openstudio-179d-worker-9rtc4-4h7g9
6m28s       Normal    Scheduled                         pod/worker-75f95467fc-85gkk                                        Successfully assigned openstudio-server/worker-75f95467fc-85gkk to openstudio-179d-worker-9rtc4-fqjr2
6m12s       Normal    Scheduled                         pod/worker-75f95467fc-v99qj                                        Successfully assigned openstudio-server/worker-75f95467fc-v99qj to openstudio-179d-worker-9rtc4-kd9zt
6m10s       Normal    Pulled                            pod/worker-75f95467fc-v99qj                                        Container image "registry-1.docker.io/nrel/openstudio-server:3.10.0" already present on machine
6m8s        Normal    Started                           pod/worker-75f95467fc-f7xs9                                        Started container worker
6m8s        Normal    Created                           pod/worker-75f95467fc-f7xs9                                        Created container: worker
5m57s       Normal    Scheduled                         pod/worker-75f95467fc-zs52m                                        Successfully assigned openstudio-server/worker-75f95467fc-zs52m to openstudio-179d-worker-9rtc4-nhmpl
5m55s       Normal    Started                           pod/worker-75f95467fc-zs52m                                        Started container worker
5m53s       Normal    Pulled                            pod/worker-75f95467fc-cg8pc                                        Container image "registry-1.docker.io/nrel/openstudio-server:3.10.0" already present on machine
5m42s       Normal    Scheduled                         pod/worker-75f95467fc-9jjmr                                        Successfully assigned openstudio-server/worker-75f95467fc-9jjmr to openstudio-179d-worker-9rtc4-s6dgq
5m34s       Warning   FailedMount                       pod/worker-75f95467fc-9jjmr                                        MountVolume.SetUp failed for volume "kube-api-access-7c4jd" : failed to fetch token: an error on the server ("<html>\r\n<head><title>502 Bad Gateway</title></head>\r\n<body>\r\n<center><h1>502 Bad Gateway</h1></center>\r\n<hr><center>nginx</center>\r\n</body>\r\n</html>") has prevented the request from succeeding (post serviceaccounts openstudio-workload)
5m27s       Normal    Scheduled                         pod/worker-75f95467fc-x52px                                        Successfully assigned openstudio-server/worker-75f95467fc-x52px to openstudio-179d-worker-9rtc4-2fg84
5m12s       Normal    Scheduled                         pod/worker-75f95467fc-vr8dw                                        Successfully assigned openstudio-server/worker-75f95467fc-vr8dw to openstudio-179d-worker-9rtc4-wf7lx
5m9s        Normal    Started                           pod/worker-75f95467fc-vr8dw                                        Started container worker
4m57s       Normal    Scheduled                         pod/worker-75f95467fc-jnmdh                                        Successfully assigned openstudio-server/worker-75f95467fc-jnmdh to openstudio-179d-worker-9rtc4-gkz2s
4m54s       Normal    Pulled                            pod/worker-75f95467fc-jnmdh                                        Container image "registry-1.docker.io/nrel/openstudio-server:3.10.0" already present on machine
4m42s       Normal    Scheduled                         pod/worker-75f95467fc-lsfsr                                        Successfully assigned openstudio-server/worker-75f95467fc-lsfsr to openstudio-179d-worker-9rtc4-8vw2k
4m36s       Warning   Failed                            pod/worker-75f95467fc-9jjmr                                        Error: failed to sync secret cache: timed out waiting for the condition
4m35s       Normal    Created                           pod/worker-75f95467fc-9jjmr                                        Created container: worker
4m27s       Normal    Scheduled                         pod/worker-75f95467fc-n8dm8                                        Successfully assigned openstudio-server/worker-75f95467fc-n8dm8 to openstudio-179d-worker-9rtc4-m2f76
4m12s       Normal    Scheduled                         pod/worker-75f95467fc-r8k6g                                        Successfully assigned openstudio-server/worker-75f95467fc-r8k6g to openstudio-179d-worker-9rtc4-zc87d
3m57s       Normal    Scheduled                         pod/worker-75f95467fc-zw8b7                                        Successfully assigned openstudio-server/worker-75f95467fc-zw8b7 to openstudio-179d-worker-9rtc4-km2jz
3m55s       Normal    EnsuringLoadBalancer              service/ingress-load-balancer                                      Ensuring load balancer
3m55s       Warning   LoadBalancerSourceRangesIgnored   service/ingress-load-balancer                                      LoadBalancerSourceRanges are ignored for Service openstudio-server/ingress-load-balancer because Octavia provider does not support it
3m49s       Warning   FailedMount                       pod/worker-75f95467fc-zw8b7                                        MountVolume.SetUp failed for volume "kube-api-access-8jqwb" : failed to fetch token: an error on the server ("<html>\r\n<head><title>502 Bad Gateway</title></head>\r\n<body>\r\n<center><h1>502 Bad Gateway</h1></center>\r\n<hr><center>nginx</center>\r\n</body>\r\n</html>") has prevented the request from succeeding (post serviceaccounts openstudio-workload)
3m42s       Normal    Scheduled                         pod/worker-75f95467fc-blp2d                                        Successfully assigned openstudio-server/worker-75f95467fc-blp2d to openstudio-179d-worker-9rtc4-zngnp
3m27s       Normal    Scheduled                         pod/worker-75f95467fc-2c57d                                        Successfully assigned openstudio-server/worker-75f95467fc-2c57d to openstudio-179d-worker-9rtc4-mftnc
3m27s       Warning   FailedMount                       pod/worker-75f95467fc-2c57d                                        MountVolume.SetUp failed for volume "kube-api-access-h77wn" : failed to fetch token: an error on the server ("<html>\r\n<head><title>502 Bad Gateway</title></head>\r\n<body>\r\n<center><h1>502 Bad Gateway</h1></center>\r\n<hr><center>nginx</center>\r\n</body>\r\n</html>") has prevented the request from succeeding (post serviceaccounts openstudio-workload)
3m26s       Normal    Pulled                            pod/worker-75f95467fc-2c57d                                        Container image "registry-1.docker.io/nrel/openstudio-server:3.10.0" already present on machine
3m25s       Normal    Pulled                            pod/worker-75f95467fc-zw8b7                                        Container image "registry-1.docker.io/nrel/openstudio-server:3.10.0" already present on machine
3m25s       Normal    Started                           pod/worker-75f95467fc-zw8b7                                        Started container worker
3m21s       Normal    Created                           pod/worker-75f95467fc-n8dm8                                        Created container: worker
3m21s       Normal    Pulled                            pod/worker-75f95467fc-n8dm8                                        Container image "registry-1.docker.io/nrel/openstudio-server:3.10.0" already present on machine
3m20s       Normal    Started                           pod/worker-75f95467fc-n8dm8                                        Started container worker
3m19s       Warning   FailedMount                       pod/worker-75f95467fc-lsfsr                                        MountVolume.SetUp failed for volume "kube-api-access-rljp5" : failed to fetch token: an error on the server ("<html>\r\n<head><title>502 Bad Gateway</title></head>\r\n<body>\r\n<center><h1>502 Bad Gateway</h1></center>\r\n<hr><center>nginx</center>\r\n</body>\r\n</html>") has prevented the request from succeeding (post serviceaccounts openstudio-workload)
3m12s       Normal    Scheduled                         pod/worker-75f95467fc-gkmq6                                        Successfully assigned openstudio-server/worker-75f95467fc-gkmq6 to openstudio-179d-worker-9rtc4-vkfwc
3m4s        Normal    Created                           pod/worker-75f95467fc-gkmq6                                        Created container: worker
3m4s        Normal    Pulled                            pod/worker-75f95467fc-gkmq6                                        Container image "registry-1.docker.io/nrel/openstudio-server:3.10.0" already present on machine
3m4s        Normal    Started                           pod/worker-75f95467fc-gkmq6                                        Started container worker
2m57s       Normal    Scheduled                         pod/worker-75f95467fc-wgc22                                        Successfully assigned openstudio-server/worker-75f95467fc-wgc22 to openstudio-179d-worker-9rtc4-zfv7b
2m56s       Normal    Created                           pod/worker-75f95467fc-wgc22                                        Created container: worker
2m51s       Warning   SyncLoadBalancerFailed            service/ingress-load-balancer                                      Error syncing load balancer: failed to ensure load balancer: Put "https://vs-api.hpc.nrel.gov:9876/v2.0/lbaas/pools/d4da9983-c8f4-4c98-8e90-0676796ab9f5/members": context deadline exceeded (Client.Timeout exceeded while awaiting headers)
2m42s       Normal    Scheduled                         pod/worker-75f95467fc-m8kx4                                        Successfully assigned openstudio-server/worker-75f95467fc-m8kx4 to openstudio-179d-worker-9rtc4-2fbn5
2m41s       Normal    Pulled                            pod/worker-75f95467fc-m8kx4                                        Container image "registry-1.docker.io/nrel/openstudio-server:3.10.0" already present on machine
2m40s       Warning   FailedMount                       pod/worker-75f95467fc-x52px                                        MountVolume.SetUp failed for volume "kube-api-access-7rsk8" : failed to fetch token: an error on the server ("<html>\r\n<head><title>502 Bad Gateway</title></head>\r\n<body>\r\n<center><h1>502 Bad Gateway</h1></center>\r\n<hr><center>nginx</center>\r\n</body>\r\n</html>") has prevented the request from succeeding (post serviceaccounts openstudio-workload)
2m27s       Normal    SuccessfulCreate                  replicaset/worker-75f95467fc                                       (combined from similar events): Created pod: worker-75f95467fc-dxcc5
2m27s       Normal    Scheduled                         pod/worker-75f95467fc-dxcc5                                        Successfully assigned openstudio-server/worker-75f95467fc-dxcc5 to openstudio-179d-worker-9rtc4-znps8
2m27s       Normal    ScalingReplicaSet                 deployment/worker                                                  (combined from similar events): Scaled up replica set worker-75f95467fc from 406 to 407
2m24s       Normal    Started                           pod/worker-75f95467fc-dxcc5                                        Started container worker
2m24s       Normal    Pulled                            pod/worker-75f95467fc-dxcc5                                        Container image "registry-1.docker.io/nrel/openstudio-server:3.10.0" already present on machine
2m24s       Normal    Created                           pod/worker-75f95467fc-dxcc5                                        Created container: worker
2m12s       Normal    Scheduled                         pod/worker-75f95467fc-5zxtb                                        Successfully assigned openstudio-server/worker-75f95467fc-5zxtb to openstudio-179d-worker-9rtc4-6p9bz
2m10s       Warning   Failed                            pod/worker-75f95467fc-5zxtb                                        Error: failed to sync secret cache: timed out waiting for the condition
2m7s        Normal    Pulled                            pod/worker-75f95467fc-lsfsr                                        Container image "registry-1.docker.io/nrel/openstudio-server:3.10.0" already present on machine
117s        Normal    Scheduled                         pod/worker-75f95467fc-bv7pc                                        Successfully assigned openstudio-server/worker-75f95467fc-bv7pc to openstudio-179d-worker-9rtc4-4h7g9
113s        Normal    Pulled                            pod/worker-75f95467fc-5zxtb                                        Container image "registry-1.docker.io/nrel/openstudio-server:3.10.0" already present on machine
113s        Normal    Started                           pod/worker-75f95467fc-5zxtb                                        Started container worker
112s        Normal    Started                           pod/worker-75f95467fc-bv7pc                                        Started container worker
112s        Normal    Created                           pod/worker-75f95467fc-bv7pc                                        Created container: worker
102s        Normal    Scheduled                         pod/worker-75f95467fc-7wwwm                                        Successfully assigned openstudio-server/worker-75f95467fc-7wwwm to openstudio-179d-worker-9rtc4-h457w
102s        Normal    SuccessfulRescale                 horizontalpodautoscaler/worker                                     (combined from similar events): New size: 486; reason: external metric s0-redis-resque-queue-simulations(&LabelSelector{MatchLabels:map[string]string{scaledobject.keda.sh/name: worker,},MatchExpressions:[]LabelSelectorRequirement{},}) above target
101s        Warning   FailedMount                       pod/worker-75f95467fc-7wwwm                                        MountVolume.SetUp failed for volume "kube-api-access-p6r2g" : failed to fetch token: an error on the server ("<html>\r\n<head><title>502 Bad Gateway</title></head>\r\n<body>\r\n<center><h1>502 Bad Gateway</h1></center>\r\n<hr><center>nginx</center>\r\n</body>\r\n</html>") has prevented the request from succeeding (post serviceaccounts openstudio-workload)
87s         Normal    Scheduled                         pod/worker-75f95467fc-zvwmh                                        Successfully assigned openstudio-server/worker-75f95467fc-zvwmh to openstudio-179d-worker-9rtc4-zc87d
85s         Normal    Created                           pod/worker-75f95467fc-zvwmh                                        Created container: worker
72s         Normal    Scheduled                         pod/worker-75f95467fc-85s5n                                        Successfully assigned openstudio-server/worker-75f95467fc-85s5n to openstudio-179d-worker-9rtc4-znps8
56s         Normal    Scheduled                         pod/worker-75f95467fc-jp8m2                                        Successfully assigned openstudio-server/worker-75f95467fc-jp8m2 to openstudio-179d-worker-9rtc4-wf7lx
56s         Warning   FailedMount                       pod/worker-75f95467fc-jp8m2                                        MountVolume.SetUp failed for volume "kube-api-access-6xxgn" : failed to fetch token: an error on the server ("<html>\r\n<head><title>502 Bad Gateway</title></head>\r\n<body>\r\n<center><h1>502 Bad Gateway</h1></center>\r\n<hr><center>nginx</center>\r\n</body>\r\n</html>") has prevented the request from succeeding (post serviceaccounts openstudio-workload)
41s         Normal    Scheduled                         pod/worker-75f95467fc-j2r7v                                        Successfully assigned openstudio-server/worker-75f95467fc-j2r7v to openstudio-179d-worker-9rtc4-zngnp
26s         Normal    Scheduled                         pod/worker-75f95467fc-25rt2                                        Successfully assigned openstudio-server/worker-75f95467fc-25rt2 to openstudio-179d-worker-9rtc4-nnnhl
26s         Normal    Pulled                            pod/worker-75f95467fc-25rt2                                        Container image "registry-1.docker.io/nrel/openstudio-server:3.10.0" already present on machine
26s         Normal    Created                           pod/worker-75f95467fc-25rt2                                        Created container: worker
11s         Normal    Scheduled                         pod/worker-75f95467fc-jxw9k                                        Successfully assigned openstudio-server/worker-75f95467fc-jxw9k to openstudio-179d-worker-9rtc4-fqjr2
11s         Warning   FailedMount                       pod/worker-75f95467fc-jxw9k                                        MountVolume.SetUp failed for volume "kube-api-access-pvdbc" : failed to fetch token: an error on the server ("<html>\r\n<head><title>502 Bad Gateway</title></head>\r\n<body>\r\n<center><h1>502 Bad Gateway</h1></center>\r\n<hr><center>nginx</center>\r\n</body>\r\n</html>") has prevented the request from succeeding (post serviceaccounts openstudio-workload)
