openstudio-server        19m         Normal    Started                           pod/worker-75f95467fc-lwz4p                                        Started container worker
openstudio-server        19m         Normal    Scheduled                         pod/worker-75f95467fc-t6zpw                                        Successfully assigned openstudio-server/worker-75f95467fc-t6zpw to openstudio-179d-worker-9rtc4-pqsdz
openstudio-server        19m         Warning   FailedMount                       pod/worker-75f95467fc-t6zpw                                        MountVolume.SetUp failed for volume "kube-api-access-bfjh8" : failed to fetch token: an error on the server ("<html>\r\n<head><title>502 Bad Gateway</title></head>\r\n<body>\r\n<center><h1>502 Bad Gateway</h1></center>\r\n<hr><center>nginx</center>\r\n</body>\r\n</html>") has prevented the request from succeeding (post serviceaccounts openstudio-workload)
kube-system              19m         Normal    Started                           pod/patch-copy-fail-hp6ds                                          Started container pause
openstudio-server        19m         Normal    Created                           pod/worker-75f95467fc-t6zpw                                        Created container: worker
openstudio-server        19m         Normal    Created                           pod/worker-54568b5fb6-x5n7x                                        Created container: worker
openstudio-server        19m         Normal    Started                           pod/worker-54568b5fb6-x5n7x                                        Started container worker
openstudio-server        19m         Normal    Scheduled                         pod/worker-54568b5fb6-x5n7x                                        Successfully assigned openstudio-server/worker-54568b5fb6-x5n7x to openstudio-179d-worker-9rtc4-pqsdz
openstudio-server        19m         Normal    Pulled                            pod/worker-54568b5fb6-x5n7x                                        Container image "registry-1.docker.io/nrel/openstudio-server:3.10.0" already present on machine
openstudio-server        19m         Warning   FailedPreStopHook                 pod/worker-75f95467fc-t6zpw                                        PreStopHook failed
openstudio-server        19m         Normal    Scheduled                         pod/worker-75f95467fc-qmzq9                                        Successfully assigned openstudio-server/worker-75f95467fc-qmzq9 to openstudio-179d-worker-9rtc4-tnv42
openstudio-server        19m         Normal    Scheduled                         pod/worker-75f95467fc-rwwdh                                        Successfully assigned openstudio-server/worker-75f95467fc-rwwdh to openstudio-179d-worker-9rtc4-tnv42
openstudio-server        19m         Normal    SuccessfulRescale                 horizontalpodautoscaler/worker                                     (combined from similar events): New size: 496; reason: external metric s0-redis-resque-queue-simulations(&LabelSelector{MatchLabels:map[string]string{scaledobject.keda.sh/name: worker,},MatchExpressions:[]LabelSelectorRequirement{},}) above target
openstudio-server        19m         Warning   FailedMount                       pod/worker-75f95467fc-rwwdh                                        MountVolume.SetUp failed for volume "kube-api-access-4hr6m" : failed to fetch token: an error on the server ("<html>\r\n<head><title>502 Bad Gateway</title></head>\r\n<body>\r\n<center><h1>502 Bad Gateway</h1></center>\r\n<hr><center>nginx</center>\r\n</body>\r\n</html>") has prevented the request from succeeding (post serviceaccounts openstudio-workload)
openstudio-server        18m         Normal    Scheduled                         pod/worker-75f95467fc-m7k8r                                        Successfully assigned openstudio-server/worker-75f95467fc-m7k8r to openstudio-179d-worker-9rtc4-tnv42
openstudio-server        18m         Normal    Pulling                           pod/worker-75f95467fc-m7k8r                                        Pulling image "registry-1.docker.io/nrel/openstudio-server:3.10.0"
openstudio-server        18m         Normal    Scheduled                         pod/worker-54568b5fb6-g4chw                                        Successfully assigned openstudio-server/worker-54568b5fb6-g4chw to openstudio-179d-worker-9rtc4-tnv42
openstudio-server        18m         Normal    Killing                           pod/worker-75f95467fc-lwz4p                                        Stopping container worker
openstudio-server        18m         Warning   FailedMount                       pod/worker-54568b5fb6-g4chw                                        MountVolume.SetUp failed for volume "kube-api-access-cbh96" : failed to fetch token: an error on the server ("<html>\r\n<head><title>502 Bad Gateway</title></head>\r\n<body>\r\n<center><h1>502 Bad Gateway</h1></center>\r\n<hr><center>nginx</center>\r\n</body>\r\n</html>") has prevented the request from succeeding (post serviceaccounts openstudio-workload)
openstudio-server        18m         Normal    Scheduled                         pod/worker-75f95467fc-sl8bg                                        Successfully assigned openstudio-server/worker-75f95467fc-sl8bg to openstudio-179d-worker-9rtc4-tnv42
openstudio-server        18m         Normal    Created                           pod/worker-75f95467fc-qmzq9                                        Created container: worker
openstudio-server        18m         Normal    Pulled                            pod/worker-75f95467fc-sl8bg                                        Successfully pulled image "registry-1.docker.io/nrel/openstudio-server:3.10.0" in 427ms (11.409s including waiting). Image size: 1855574783 bytes.
openstudio-server        18m         Normal    Pulled                            pod/worker-54568b5fb6-g4chw                                        Successfully pulled image "registry-1.docker.io/nrel/openstudio-server:3.10.0" in 406ms (10.292s including waiting). Image size: 1855574783 bytes.
openstudio-server        18m         Normal    Started                           pod/worker-75f95467fc-sl8bg                                        Started container worker
openstudio-server        18m         Normal    Created                           pod/worker-54568b5fb6-g4chw                                        Created container: worker
openstudio-server        18m         Normal    Scheduled                         pod/worker-75f95467fc-pdw6w                                        Successfully assigned openstudio-server/worker-75f95467fc-pdw6w to openstudio-179d-worker-9rtc4-tnv42
openstudio-server        18m         Normal    Scheduled                         pod/worker-54568b5fb6-l2tf5                                        Successfully assigned openstudio-server/worker-54568b5fb6-l2tf5 to openstudio-179d-worker-9rtc4-tnv42
openstudio-server        18m         Normal    Scheduled                         pod/worker-75f95467fc-g2gdq                                        Successfully assigned openstudio-server/worker-75f95467fc-g2gdq to openstudio-179d-worker-9rtc4-tnv42
openstudio-server        18m         Normal    Pulled                            pod/worker-54568b5fb6-l2tf5                                        Container image "registry-1.docker.io/nrel/openstudio-server:3.10.0" already present on machine
openstudio-server        17m         Normal    Scheduled                         pod/worker-54568b5fb6-dwcvq                                        Successfully assigned openstudio-server/worker-54568b5fb6-dwcvq to openstudio-179d-worker-9rtc4-tnv42
openstudio-server        17m         Warning   FailedMount                       pod/worker-54568b5fb6-dwcvq                                        MountVolume.SetUp failed for volume "kube-api-access-zx8x4" : failed to fetch token: an error on the server ("<html>\r\n<head><title>502 Bad Gateway</title></head>\r\n<body>\r\n<center><h1>502 Bad Gateway</h1></center>\r\n<hr><center>nginx</center>\r\n</body>\r\n</html>") has prevented the request from succeeding (post serviceaccounts openstudio-workload)
openstudio-server        17m         Normal    Created                           pod/worker-54568b5fb6-dwcvq                                        Created container: worker
openstudio-server        17m         Normal    Scheduled                         pod/worker-75f95467fc-m6jwz                                        Successfully assigned openstudio-server/worker-75f95467fc-m6jwz to openstudio-179d-worker-9rtc4-tnv42
openstudio-server        17m         Normal    Scheduled                         pod/worker-75f95467fc-4tt6t                                        Successfully assigned openstudio-server/worker-75f95467fc-4tt6t to openstudio-179d-worker-9rtc4-tnv42
openstudio-server        17m         Normal    Created                           pod/worker-75f95467fc-4tt6t                                        Created container: worker
openstudio-server        17m         Normal    Started                           pod/worker-75f95467fc-4tt6t                                        Started container worker
openstudio-server        17m         Normal    Scheduled                         pod/worker-54568b5fb6-ccpxb                                        Successfully assigned openstudio-server/worker-54568b5fb6-ccpxb to openstudio-179d-worker-9rtc4-964ml
openstudio-server        17m         Normal    Killing                           pod/worker-75f95467fc-4tt6t                                        Stopping container worker
openstudio-server        17m         Normal    Scheduled                         pod/worker-75f95467fc-kl888                                        Successfully assigned openstudio-server/worker-75f95467fc-kl888 to openstudio-179d-worker-9rtc4-9gk7k
openstudio-server        17m         Normal    Scheduled                         pod/worker-75f95467fc-8qwlv                                        Successfully assigned openstudio-server/worker-75f95467fc-8qwlv to openstudio-179d-worker-9rtc4-xh26n
openstudio-server        16m         Normal    Scheduled                         pod/worker-75f95467fc-xtszh                                        Successfully assigned openstudio-server/worker-75f95467fc-xtszh to openstudio-179d-worker-9rtc4-9gk7k
openstudio-server        16m         Normal    Started                           pod/worker-75f95467fc-xtszh                                        Started container worker
openstudio-server        16m         Normal    Started                           pod/worker-54568b5fb6-ccpxb                                        Started container worker
openstudio-server        16m         Normal    Pulled                            pod/worker-54568b5fb6-ccpxb                                        Successfully pulled image "registry-1.docker.io/nrel/openstudio-server:3.10.0" in 55.184s (55.184s including waiting). Image size: 1855574783 bytes.
openstudio-server        16m         Normal    Created                           pod/worker-54568b5fb6-ccpxb                                        Created container: worker
openstudio-server        16m         Warning   FailedMount                       pod/worker-75f95467fc-vzb29                                        MountVolume.SetUp failed for volume "kube-api-access-g9rsd" : failed to fetch token: an error on the server ("<html>\r\n<head><title>502 Bad Gateway</title></head>\r\n<body>\r\n<center><h1>502 Bad Gateway</h1></center>\r\n<hr><center>nginx</center>\r\n</body>\r\n</html>") has prevented the request from succeeding (post serviceaccounts openstudio-workload)
openstudio-server        16m         Normal    Scheduled                         pod/worker-75f95467fc-vzb29                                        Successfully assigned openstudio-server/worker-75f95467fc-vzb29 to openstudio-179d-worker-9rtc4-964ml
openstudio-server        16m         Normal    Pulled                            pod/worker-75f95467fc-vzb29                                        Container image "registry-1.docker.io/nrel/openstudio-server:3.10.0" already present on machine
openstudio-server        16m         Normal    Scheduled                         pod/worker-54568b5fb6-9npdd                                        Successfully assigned openstudio-server/worker-54568b5fb6-9npdd to openstudio-179d-worker-9rtc4-xh26n
ingress-nginx            16m         Warning   SyncLoadBalancerFailed            service/ingress-nginx-controller                                   Error syncing load balancer: failed to ensure load balancer: Put "https://vs-api.hpc.nrel.gov:9876/v2.0/lbaas/pools/fe769bc3-a1ec-44a2-b1ba-983a0802b93d/members": context deadline exceeded (Client.Timeout exceeded while awaiting headers)
kube-system              16m         Normal    LeaderElection                    lease/cluster-autoscaler                                           openstudio-179d-autoscaler-74d5694874-268wd became leader
openstudio-server        16m         Normal    Scheduled                         pod/worker-75f95467fc-9swsz                                        Successfully assigned openstudio-server/worker-75f95467fc-9swsz to openstudio-179d-worker-9rtc4-964ml
openstudio-server        16m         Normal    Started                           pod/worker-75f95467fc-9swsz                                        Started container worker
openstudio-server        16m         Normal    Pulled                            pod/worker-75f95467fc-9swsz                                        Container image "registry-1.docker.io/nrel/openstudio-server:3.10.0" already present on machine
default                  16m         Normal    NodeNotSchedulable                node/openstudio-179d-worker-9rtc4-xlk89                            Node openstudio-179d-worker-9rtc4-xlk89 status is now: NodeNotSchedulable
openstudio-server        16m         Normal    Scheduled                         pod/worker-75f95467fc-dn7xw                                        Successfully assigned openstudio-server/worker-75f95467fc-dn7xw to openstudio-179d-worker-9rtc4-xh26n
node-problem-detector    16m         Warning   NetworkNotReady                   pod/node-problem-detector-ppp56                                    network is not ready: container runtime network not ready: NetworkReady=false reason:NetworkPluginNotReady message:Network plugin returns error: cni plugin not initialized
calico-system            16m         Warning   NetworkNotReady                   pod/csi-node-driver-9mbqm                                          network is not ready: container runtime network not ready: NetworkReady=false reason:NetworkPluginNotReady message:Network plugin returns error: cni plugin not initialized
openstudio-server        15m         Normal    Pulled                            pod/worker-75f95467fc-8qwlv                                        Successfully pulled image "registry-1.docker.io/nrel/openstudio-server:3.10.0" in 56.79s (56.79s including waiting). Image size: 1855574783 bytes.
openstudio-server        15m         Normal    Started                           pod/worker-75f95467fc-8qwlv                                        Started container worker
openstudio-server        15m         Normal    Created                           pod/worker-75f95467fc-8qwlv                                        Created container: worker
openstudio-server        15m         Normal    Scheduled                         pod/worker-75f95467fc-t8fr4                                        Successfully assigned openstudio-server/worker-75f95467fc-t8fr4 to openstudio-179d-worker-9rtc4-xh26n
openstudio-server        15m         Normal    Scheduled                         pod/worker-75f95467fc-jczhj                                        Successfully assigned openstudio-server/worker-75f95467fc-jczhj to openstudio-179d-worker-9rtc4-xh26n
openstudio-server        14m         Warning   FailedMount                       pod/worker-54568b5fb6-4t9wg                                        MountVolume.SetUp failed for volume "kube-api-access-52tdl" : failed to fetch token: an error on the server ("<html>\r\n<head><title>502 Bad Gateway</title></head>\r\n<body>\r\n<center><h1>502 Bad Gateway</h1></center>\r\n<hr><center>nginx</center>\r\n</body>\r\n</html>") has prevented the request from succeeding (post serviceaccounts openstudio-workload)
kube-system              14m         Normal    Scheduled                         pod/vm-max-map-count-enforcer-jlhs4                                Successfully assigned kube-system/vm-max-map-count-enforcer-jlhs4 to openstudio-179d-worker-9rtc4-xlk89
kube-system              14m         Warning   FailedMount                       pod/vm-max-map-count-enforcer-jlhs4                                MountVolume.SetUp failed for volume "kube-api-access-v9q2q" : failed to fetch token: an error on the server ("<html>\r\n<head><title>502 Bad Gateway</title></head>\r\n<body>\r\n<center><h1>502 Bad Gateway</h1></center>\r\n<hr><center>nginx</center>\r\n</body>\r\n</html>") has prevented the request from succeeding (post serviceaccounts default)
kube-system              14m         Normal    SuccessfulCreate                  daemonset/vm-max-map-count-enforcer                                Created pod: vm-max-map-count-enforcer-jlhs4
openstudio-server        14m         Warning   FailedPreStopHook                 pod/worker-75f95467fc-8qwlv                                        PreStopHook failed
openstudio-server        14m         Normal    Started                           pod/worker-75f95467fc-t8fr4                                        Started container worker
openstudio-server        14m         Warning   FailedMount                       pod/worker-54568b5fb6-9npdd                                        MountVolume.SetUp failed for volume "kube-api-access-n9fl4" : failed to fetch token: an error on the server ("<html>\r\n<head><title>502 Bad Gateway</title></head>\r\n<body>\r\n<center><h1>502 Bad Gateway</h1></center>\r\n<hr><center>nginx</center>\r\n</body>\r\n</html>") has prevented the request from succeeding (post serviceaccounts openstudio-workload)
openstudio-server        14m         Normal    Created                           pod/worker-75f95467fc-jczhj                                        Created container: worker
kube-system              14m         Warning   NetworkNotReady                   pod/vm-max-map-count-enforcer-jlhs4                                network is not ready: container runtime network not ready: NetworkReady=false reason:NetworkPluginNotReady message:Network plugin returns error: cni plugin not initialized
node-feature-discovery   14m         Normal    SuccessfulCreate                  daemonset/node-feature-discovery-worker                            Created pod: node-feature-discovery-worker-6ncdj
node-feature-discovery   14m         Normal    Scheduled                         pod/node-feature-discovery-worker-6ncdj                            Successfully assigned node-feature-discovery/node-feature-discovery-worker-6ncdj to openstudio-179d-worker-9rtc4-xlk89
kube-system              14m         Normal    SuccessfulCreate                  daemonset/vm-max-map-count-enforcer                                (combined from similar events): Created pod: vm-max-map-count-enforcer-vj2mw
kube-system              14m         Normal    Scheduled                         pod/vm-max-map-count-enforcer-vj2mw                                Successfully assigned kube-system/vm-max-map-count-enforcer-vj2mw to openstudio-179d-worker-9rtc4-xlk89
node-feature-discovery   14m         Warning   FailedMount                       pod/node-feature-discovery-worker-6ncdj                            MountVolume.SetUp failed for volume "nfd-worker-conf" : object "node-feature-discovery"/"node-feature-discovery-worker-conf" not registered
openstudio-server        13m         Warning   FailedMount                       pod/worker-75f95467fc-dn7xw                                        MountVolume.SetUp failed for volume "kube-api-access-j7jgx" : failed to fetch token: an error on the server ("<html>\r\n<head><title>502 Bad Gateway</title></head>\r\n<body>\r\n<center><h1>502 Bad Gateway</h1></center>\r\n<hr><center>nginx</center>\r\n</body>\r\n</html>") has prevented the request from succeeding (post serviceaccounts openstudio-workload)
openstudio-server        13m         Normal    SuccessfulCreate                  replicaset/openstudio-server-nfs-server-provisioner-6bf4f79c4      Created pod: openstudio-server-nfs-server-provisioner-6bf4f79c4-jcz6f
openstudio-server        13m         Warning   FailedAttachVolume                pod/openstudio-server-nfs-server-provisioner-6bf4f79c4-jcz6f       Multi-Attach error for volume "pvc-94566787-6dd6-400a-94a4-339f7012de02" Volume is already used by pod(s) openstudio-server-nfs-server-provisioner-6bf4f79c4-g8p9n
openstudio-server        13m         Normal    Killing                           pod/openstudio-server-nfs-server-provisioner-6bf4f79c4-g8p9n       Stopping container nfs-server-provisioner
openstudio-server        13m         Normal    Scheduled                         pod/openstudio-server-nfs-server-provisioner-6bf4f79c4-jcz6f       Successfully assigned openstudio-server/openstudio-server-nfs-server-provisioner-6bf4f79c4-jcz6f to openstudio-179d-web-tq5p9-mrcgs
openstudio-server        13m         Warning   FailedMount                       pod/openstudio-server-nfs-server-provisioner-6bf4f79c4-jcz6f       Unable to attach or mount volumes: unmounted volumes=[data kube-api-access-h6r66], unattached volumes=[], failed to process volumes=[data]: error processing PVC openstudio-server/nfs-pvc-data: failed to fetch PV pvc-94566787-6dd6-400a-94a4-339f7012de02 from API server: an error on the server ("<html>\r\n<head><title>502 Bad Gateway</title></head>\r\n<body>\r\n<center><h1>502 Bad Gateway</h1></center>\r\n<hr><center>nginx</center>\r\n</body>\r\n</html>") has prevented the request from succeeding (get persistentvolumes pvc-94566787-6dd6-400a-94a4-339f7012de02)
openstack-system         13m         Normal    SuccessfulCreate                  daemonset/openstack-cinder-csi-nodeplugin                          Created pod: openstack-cinder-csi-nodeplugin-85clw
openstack-system         13m         Normal    Scheduled                         pod/openstack-cinder-csi-nodeplugin-85clw                          Successfully assigned openstack-system/openstack-cinder-csi-nodeplugin-85clw to openstudio-179d-worker-9rtc4-xlk89
openstack-system         13m         Normal    Created                           pod/openstack-cinder-csi-nodeplugin-85clw                          Created container: cinder-csi-plugin
openstack-system         13m         Normal    Started                           pod/openstack-cinder-csi-nodeplugin-85clw                          Started container cinder-csi-plugin
openstack-system         13m         Normal    Pulled                            pod/openstack-cinder-csi-nodeplugin-85clw                          Container image "registry.k8s.io/sig-storage/csi-node-driver-registrar:v2.12.0" already present on machine
openstack-system         13m         Normal    Created                           pod/openstack-cinder-csi-nodeplugin-85clw                          Created container: liveness-probe
openstack-system         13m         Normal    Started                           pod/openstack-cinder-csi-nodeplugin-85clw                          Started container node-driver-registrar
openstack-system         13m         Normal    Started                           pod/openstack-cinder-csi-nodeplugin-85clw                          Started container liveness-probe
openstack-system         13m         Normal    Pulled                            pod/openstack-cinder-csi-nodeplugin-85clw                          Container image "registry.k8s.io/provider-os/cinder-csi-plugin:v1.32.0" already present on machine
openstudio-server        13m         Normal    Scheduled                         pod/worker-54568b5fb6-87dxp                                        Successfully assigned openstudio-server/worker-54568b5fb6-87dxp to openstudio-179d-worker-9rtc4-xh26n
openstudio-server        13m         Normal    Created                           pod/worker-54568b5fb6-87dxp                                        Created container: worker
openstudio-server        13m         Normal    Scheduled                         pod/worker-54568b5fb6-nm5pb                                        Successfully assigned openstudio-server/worker-54568b5fb6-nm5pb to openstudio-179d-worker-9rtc4-xh26n
openstudio-server        13m         Normal    Preempted                         pod/worker-75f95467fc-ls79l                                        Preempted by pod 4655c9b8-f86a-4af0-8f21-fc7e30cf86b1 on node openstudio-179d-web-tq5p9-v5jpg
openstudio-server        13m         Warning   FailedMount                       pod/worker-54568b5fb6-nm5pb                                        MountVolume.SetUp failed for volume "kube-api-access-rdk9w" : failed to fetch token: an error on the server ("<html>\r\n<head><title>502 Bad Gateway</title></head>\r\n<body>\r\n<center><h1>502 Bad Gateway</h1></center>\r\n<hr><center>nginx</center>\r\n</body>\r\n</html>") has prevented the request from succeeding (post serviceaccounts openstudio-workload)
openstudio-server        13m         Warning   FailedScheduling                  pod/web-5f9c6bbcb6-tm56n                                           0/166 nodes are available: 1 node(s) were unschedulable, 159 node(s) didn't match Pod's node affinity/selector, 3 Insufficient cpu, 3 node(s) had untolerated taint {node-role.kubernetes.io/control-plane: }.
openstudio-server        13m         Normal    Preempted                         pod/worker-54568b5fb6-4jb9m                                        Preempted by pod 4655c9b8-f86a-4af0-8f21-fc7e30cf86b1 on node openstudio-179d-web-tq5p9-v5jpg
openstudio-server        13m         Normal    Preempted                         pod/worker-75f95467fc-jrx6f                                        Preempted by pod 4655c9b8-f86a-4af0-8f21-fc7e30cf86b1 on node openstudio-179d-web-tq5p9-v5jpg
openstudio-server        13m         Normal    SuccessfulCreate                  replicaset/web-5f9c6bbcb6                                          Created pod: web-5f9c6bbcb6-tm56n
openstudio-server        13m         Normal    Started                           pod/worker-54568b5fb6-nm5pb                                        Started container worker
openstudio-server        13m         Normal    Scheduled                         pod/worker-54568b5fb6-5ssfr                                        Successfully assigned openstudio-server/worker-54568b5fb6-5ssfr to openstudio-179d-worker-9rtc4-xh26n
kube-system              13m         Warning   NetworkNotReady                   pod/vm-max-map-count-enforcer-vj2mw                                network is not ready: container runtime network not ready: NetworkReady=false reason:NetworkPluginNotReady message:Network plugin returns error: cni plugin not initialized
openstudio-server        13m         Normal    SuccessfulAttachVolume            pod/openstudio-server-nfs-server-provisioner-6bf4f79c4-jcz6f       AttachVolume.Attach succeeded for volume "pvc-94566787-6dd6-400a-94a4-339f7012de02"
openstudio-server        13m         Normal    Killing                           pod/worker-75f95467fc-q6v95                                        Stopping container worker
openstudio-server        13m         Normal    Scheduled                         pod/worker-54568b5fb6-47wrz                                        Successfully assigned openstudio-server/worker-54568b5fb6-47wrz to openstudio-179d-worker-9rtc4-xh26n
openstudio-server        13m         Warning   FailedScheduling                  pod/web-5f9c6bbcb6-tm56n                                           0/166 nodes are available: 1 node(s) were unschedulable, 159 node(s) didn't match Pod's node affinity/selector, 3 Insufficient cpu, 3 node(s) had untolerated taint {node-role.kubernetes.io/control-plane: }. preemption: not eligible due to a terminating pod on the nominated node.
openstudio-server        13m         Normal    Pulled                            pod/worker-54568b5fb6-47wrz                                        Container image "registry-1.docker.io/nrel/openstudio-server:3.10.0" already present on machine
openstudio-server        13m         Normal    Started                           pod/worker-54568b5fb6-47wrz                                        Started container worker
default                  13m         Normal    DeletingNode                      node/openstudio-179d-worker-9rtc4-xlk89                            Deleting node openstudio-179d-worker-9rtc4-xlk89 because it does not exist in the cloud provider
openstudio-server        13m         Normal    Started                           pod/worker-54568b5fb6-gzsg6                                        Started container worker
openstudio-server        13m         Normal    Scheduled                         pod/worker-54568b5fb6-gzsg6                                        Successfully assigned openstudio-server/worker-54568b5fb6-gzsg6 to openstudio-179d-worker-9rtc4-xh26n
openstudio-server        13m         Normal    Pulled                            pod/worker-54568b5fb6-gzsg6                                        Container image "registry-1.docker.io/nrel/openstudio-server:3.10.0" already present on machine
default                  13m         Normal    RemovingNode                      node/openstudio-179d-worker-9rtc4-xlk89                            Node openstudio-179d-worker-9rtc4-xlk89 event: Removing Node openstudio-179d-worker-9rtc4-xlk89 from Controller
openstudio-server        13m         Warning   FailedPreStopHook                 pod/worker-75f95467fc-jczhj                                        PreStopHook failed
openstudio-server        13m         Normal    Scheduled                         pod/worker-54568b5fb6-tgnjr                                        Successfully assigned openstudio-server/worker-54568b5fb6-tgnjr to openstudio-179d-worker-9rtc4-xh26n
openstudio-server        13m         Normal    Started                           pod/worker-54568b5fb6-tgnjr                                        Started container worker
openstudio-server        13m         Normal    Started                           pod/openstudio-server-nfs-server-provisioner-6bf4f79c4-jcz6f       Started container nfs-server-provisioner
openstudio-server        12m         Normal    Pulled                            pod/worker-54568b5fb6-4t9wg                                        Container image "registry-1.docker.io/nrel/openstudio-server:3.10.0" already present on machine
openstudio-server        12m         Normal    Started                           pod/worker-54568b5fb6-4t9wg                                        Started container worker
openstudio-server        12m         Normal    Created                           pod/worker-54568b5fb6-4t9wg                                        Created container: worker
openstudio-server        12m         Normal    Scheduled                         pod/web-5f9c6bbcb6-tm56n                                           Successfully assigned openstudio-server/web-5f9c6bbcb6-tm56n to openstudio-179d-web-tq5p9-v5jpg
openstack-system         12m         Normal    Scheduled                         pod/openstack-cinder-csi-nodeplugin-lttcb                          Successfully assigned openstack-system/openstack-cinder-csi-nodeplugin-lttcb to openstudio-179d-worker-9rtc4-pqzdb
calico-system            12m         Normal    Scheduled                         pod/csi-node-driver-zxvq2                                          Successfully assigned calico-system/csi-node-driver-zxvq2 to openstudio-179d-worker-9rtc4-pqzdb
default                  12m         Normal    Synced                            node/openstudio-179d-worker-9rtc4-pqzdb                            Node synced successfully
openstack-system         12m         Normal    SuccessfulCreate                  daemonset/openstack-cinder-csi-nodeplugin                          (combined from similar events): Created pod: openstack-cinder-csi-nodeplugin-lttcb
monitoring-system        12m         Normal    Scheduled                         pod/kube-prometheus-stack-prometheus-node-exporter-qptrn           Successfully assigned monitoring-system/kube-prometheus-stack-prometheus-node-exporter-qptrn to openstudio-179d-worker-9rtc4-pqzdb
node-feature-discovery   12m         Normal    Scheduled                         pod/node-feature-discovery-worker-vz5fq                            Successfully assigned node-feature-discovery/node-feature-discovery-worker-vz5fq to openstudio-179d-worker-9rtc4-pqzdb
openstudio-server        12m         Normal    LeaderElection                    endpoints/cluster.local-openstudio-server-nfs-server-provisioner   openstudio-server-nfs-server-provisioner-6bf4f79c4-jcz6f_16a7c45b-18be-4166-ac0c-cd406f6a947c became leader
kube-system              12m         Normal    Scheduled                         pod/vm-max-map-count-enforcer-8k6b5                                Successfully assigned kube-system/vm-max-map-count-enforcer-8k6b5 to openstudio-179d-worker-9rtc4-pqzdb
calico-system            12m         Normal    Scheduled                         pod/calico-node-qnszk                                              Successfully assigned calico-system/calico-node-qnszk to openstudio-179d-worker-9rtc4-pqzdb
calico-system            12m         Normal    SuccessfulCreate                  daemonset/calico-node                                              Created pod: calico-node-qnszk
monitoring-system        12m         Normal    SuccessfulCreate                  daemonset/kube-prometheus-stack-prometheus-node-exporter           Created pod: kube-prometheus-stack-prometheus-node-exporter-qptrn
kube-system              12m         Normal    SuccessfulCreate                  daemonset/kube-proxy                                               Created pod: kube-proxy-zz8rg
kube-system              12m         Normal    Scheduled                         pod/kube-proxy-zz8rg                                               Successfully assigned kube-system/kube-proxy-zz8rg to openstudio-179d-worker-9rtc4-pqzdb
node-problem-detector    12m         Normal    Scheduled                         pod/node-problem-detector-n4t95                                    Successfully assigned node-problem-detector/node-problem-detector-n4t95 to openstudio-179d-worker-9rtc4-pqzdb
node-problem-detector    12m         Normal    SuccessfulCreate                  daemonset/node-problem-detector                                    Created pod: node-problem-detector-n4t95
calico-system            12m         Normal    SuccessfulCreate                  daemonset/csi-node-driver                                          Created pod: csi-node-driver-zxvq2
node-feature-discovery   12m         Normal    SuccessfulCreate                  daemonset/node-feature-discovery-worker                            (combined from similar events): Created pod: node-feature-discovery-worker-vz5fq
kube-system              12m         Warning   FailedMount                       pod/kube-proxy-zz8rg                                               MountVolume.SetUp failed for volume "kube-api-access-rrdtd" : failed to fetch token: an error on the server ("<html>\r\n<head><title>502 Bad Gateway</title></head>\r\n<body>\r\n<center><h1>502 Bad Gateway</h1></center>\r\n<hr><center>nginx</center>\r\n</body>\r\n</html>") has prevented the request from succeeding (post serviceaccounts kube-proxy)
calico-system            12m         Warning   FailedMount                       pod/csi-node-driver-zxvq2                                          MountVolume.SetUp failed for volume "kube-api-access-4m5hf" : failed to fetch token: an error on the server ("<html>\r\n<head><title>502 Bad Gateway</title></head>\r\n<body>\r\n<center><h1>502 Bad Gateway</h1></center>\r\n<hr><center>nginx</center>\r\n</body>\r\n</html>") has prevented the request from succeeding (post serviceaccounts csi-node-driver)
node-problem-detector    12m         Warning   FailedMount                       pod/node-problem-detector-n4t95                                    MountVolume.SetUp failed for volume "kube-api-access-f8k7f" : [failed to fetch token: an error on the server ("<html>\r\n<head><title>502 Bad Gateway</title></head>\r\n<body>\r\n<center><h1>502 Bad Gateway</h1></center>\r\n<hr><center>nginx</center>\r\n</body>\r\n</html>") has prevented the request from succeeding (post serviceaccounts node-problem-detector), object "node-problem-detector"/"kube-root-ca.crt" not registered]
kube-system              12m         Warning   FailedMount                       pod/kube-proxy-zz8rg                                               MountVolume.SetUp failed for volume "kube-proxy" : failed to sync configmap cache: timed out waiting for the condition
default                  12m         Normal    RegisteredNode                    node/openstudio-179d-worker-9rtc4-pqzdb                            Node openstudio-179d-worker-9rtc4-pqzdb event: Registered Node openstudio-179d-worker-9rtc4-pqzdb in Controller
openstudio-server        12m         Normal    Killing                           pod/worker-75f95467fc-t8fr4                                        Stopping container worker
node-feature-discovery   12m         Warning   FailedMount                       pod/node-feature-discovery-worker-vz5fq                            MountVolume.SetUp failed for volume "nfd-worker-conf" : object "node-feature-discovery"/"node-feature-discovery-worker-conf" not registered
openstudio-server        12m         Normal    Scheduled                         pod/worker-54568b5fb6-jnqkq                                        Successfully assigned openstudio-server/worker-54568b5fb6-jnqkq to openstudio-179d-worker-9rtc4-xh26n
openstudio-server        12m         Warning   FailedPreStopHook                 pod/worker-75f95467fc-t8fr4                                        PreStopHook failed
openstudio-server        12m         Warning   FailedPreStopHook                 pod/worker-75f95467fc-pdw6w                                        PreStopHook failed
openstudio-server        12m         Normal    Scheduled                         pod/worker-54568b5fb6-5vzrq                                        Successfully assigned openstudio-server/worker-54568b5fb6-5vzrq to openstudio-179d-worker-9rtc4-964ml
openstudio-server        12m         Normal    Created                           pod/worker-54568b5fb6-5vzrq                                        Created container: worker
kube-system              12m         Normal    Pulled                            pod/kube-proxy-zz8rg                                               Container image "registry.k8s.io/kube-proxy:v1.33.1" already present on machine
calico-system            12m         Normal    Pulling                           pod/calico-node-qnszk                                              Pulling image "docker.io/calico/pod2daemon-flexvol:v3.29.3"
openstudio-server        12m         Normal    Started                           pod/worker-54568b5fb6-5vzrq                                        Started container worker
monitoring-system        12m         Normal    Pulling                           pod/kube-prometheus-stack-prometheus-node-exporter-qptrn           Pulling image "quay.io/prometheus/node-exporter:v1.8.2"
node-problem-detector    12m         Warning   FailedMount                       pod/node-problem-detector-n4t95                                    MountVolume.SetUp failed for volume "kube-api-access-f8k7f" : object "node-problem-detector"/"kube-root-ca.crt" not registered
calico-system            12m         Normal    Pulled                            pod/calico-node-qnszk                                              Successfully pulled image "docker.io/calico/pod2daemon-flexvol:v3.29.3" in 1.557s (1.557s including waiting). Image size: 6860137 bytes.
node-problem-detector    12m         Warning   FailedMount                       pod/node-problem-detector-n4t95                                    MountVolume.SetUp failed for volume "custom-config" : object "node-problem-detector"/"node-problem-detector-custom-config" not registered
kube-system              12m         Warning   FailedToUpdateEndpointSlices      service/kube-prometheus-stack-kube-proxy                           Error updating Endpoint Slices for Service kube-system/kube-prometheus-stack-kube-proxy: skipping Pod kube-proxy-c7r4r for Service kube-system/kube-prometheus-stack-kube-proxy: Node openstudio-179d-worker-9rtc4-xlk89 Not Found
calico-system            12m         Warning   NetworkNotReady                   pod/csi-node-driver-zxvq2                                          network is not ready: container runtime network not ready: NetworkReady=false reason:NetworkPluginNotReady message:Network plugin returns error: cni plugin not initialized
node-feature-discovery   12m         Warning   FailedMount                       pod/node-feature-discovery-worker-vz5fq                            MountVolume.SetUp failed for volume "kube-api-access-x67sm" : [failed to fetch token: an error on the server ("<html>\r\n<head><title>502 Bad Gateway</title></head>\r\n<body>\r\n<center><h1>502 Bad Gateway</h1></center>\r\n<hr><center>nginx</center>\r\n</body>\r\n</html>") has prevented the request from succeeding (post serviceaccounts node-feature-discovery-worker), object "node-feature-discovery"/"kube-root-ca.crt" not registered]
calico-system            12m         Normal    Pulling                           pod/calico-node-qnszk                                              Pulling image "docker.io/calico/cni:v3.29.3"
monitoring-system        12m         Normal    Started                           pod/kube-prometheus-stack-prometheus-node-exporter-qptrn           Started container node-exporter
kube-system              12m         Warning   NetworkNotReady                   pod/vm-max-map-count-enforcer-8k6b5                                network is not ready: container runtime network not ready: NetworkReady=false reason:NetworkPluginNotReady message:Network plugin returns error: cni plugin not initialized
node-feature-discovery   12m         Warning   NetworkNotReady                   pod/node-feature-discovery-worker-vz5fq                            network is not ready: container runtime network not ready: NetworkReady=false reason:NetworkPluginNotReady message:Network plugin returns error: cni plugin not initialized
calico-system            12m         Warning   FailedToUpdateEndpointSlices      service/cni-calico-monitoring-node                                 Error updating Endpoint Slices for Service calico-system/cni-calico-monitoring-node: skipping Pod calico-node-bj4x5 for Service calico-system/cni-calico-monitoring-node: Node openstudio-179d-worker-9rtc4-xlk89 Not Found
node-problem-detector    12m         Warning   NetworkNotReady                   pod/node-problem-detector-n4t95                                    network is not ready: container runtime network not ready: NetworkReady=false reason:NetworkPluginNotReady message:Network plugin returns error: cni plugin not initialized
calico-system            12m         Warning   FailedCreatePodSandBox            pod/csi-node-driver-zxvq2                                          Failed to create pod sandbox: rpc error: code = Unknown desc = failed to setup network for sandbox "d71bae002a6c7a999ec78cd464cf56dcd2ebdf387a1928fae50b4d204f541302": plugin type="calico" failed (add): stat /var/lib/calico/nodename: no such file or directory: check that the calico/node container is running and has mounted /var/lib/calico/
openstack-system         12m         Normal    Started                           pod/openstack-cinder-csi-nodeplugin-lttcb                          Started container liveness-probe
monitoring-system        12m         Normal    SuccessfulCreate                  daemonset/loki-stack-promtail                                      Created pod: loki-stack-promtail-fgrhv
kube-system              12m         Normal    Scheduled                         pod/patch-copy-fail-txcs2                                          Successfully assigned kube-system/patch-copy-fail-txcs2 to openstudio-179d-worker-9rtc4-pqzdb
monitoring-system        12m         Warning   FailedToUpdateEndpointSlices      service/kube-prometheus-stack-prometheus-node-exporter             Error updating Endpoint Slices for Service monitoring-system/kube-prometheus-stack-prometheus-node-exporter: skipping Pod kube-prometheus-stack-prometheus-node-exporter-qhd64 for Service monitoring-system/kube-prometheus-stack-prometheus-node-exporter: Node openstudio-179d-worker-9rtc4-xlk89 Not Found
monitoring-system        12m         Normal    Scheduled                         pod/loki-stack-promtail-fgrhv                                      Successfully assigned monitoring-system/loki-stack-promtail-fgrhv to openstudio-179d-worker-9rtc4-pqzdb
kube-system              12m         Normal    SuccessfulCreate                  daemonset/patch-copy-fail                                          Created pod: patch-copy-fail-txcs2
kube-system              12m         Warning   FailedCreatePodSandBox            pod/patch-copy-fail-txcs2                                          Failed to create pod sandbox: rpc error: code = Unknown desc = failed to setup network for sandbox "eb5500ffd9667671edca3dc16ac7bb1b92ab6ef4117d0cdbfe662f68c44deda9": plugin type="calico" failed (add): stat /var/lib/calico/nodename: no such file or directory: check that the calico/node container is running and has mounted /var/lib/calico/
monitoring-system        12m         Warning   FailedMount                       pod/loki-stack-promtail-fgrhv                                      MountVolume.SetUp failed for volume "kube-api-access-tkkzs" : [failed to fetch token: an error on the server ("<html>\r\n<head><title>502 Bad Gateway</title></head>\r\n<body>\r\n<center><h1>502 Bad Gateway</h1></center>\r\n<hr><center>nginx</center>\r\n</body>\r\n</html>") has prevented the request from succeeding (post serviceaccounts loki-stack-promtail), failed to sync configmap cache: timed out waiting for the condition]
monitoring-system        12m         Warning   FailedCreatePodSandBox            pod/loki-stack-promtail-fgrhv                                      Failed to create pod sandbox: rpc error: code = Unknown desc = failed to setup network for sandbox "0b4d62525cca3273e48096e4dd140b4ca03a35c828afed3fac4262771868dfb7": plugin type="calico" failed (add): stat /var/lib/calico/nodename: no such file or directory: check that the calico/node container is running and has mounted /var/lib/calico/
openstudio-server        12m         Warning   UpdateLoadBalancerFailed          service/ingress-load-balancer                                      Error updating load balancer with new hosts [openstudio-179d-worker-9rtc4-784j2 openstudio-179d-worker-9rtc4-9gk7k openstudio-179d-worker-9rtc4-blz8r openstudio-179d-worker-9rtc4-hjgnv openstudio-179d-worker-9rtc4-k82wq openstudio-179d-worker-9rtc4-kqcnq openstudio-179d-worker-9rtc4-lz8v6 openstudio-179d-worker-9rtc4-mdb5p openstudio-179d-worker-9rtc4-mftnc openstudio-179d-worker-9rtc4-mll2j openstudio-179d-worker-9rtc4-msgfj openstudio-179d-worker-9rtc4-pmfzl openstudio-179d-worker-9rtc4-pzl68 openstudio-179d-worker-9rtc4-tnv42 openstudio-179d-worker-9rtc4-vxhbk openstudio-179d-worker-9rtc4-wl7tq openstudio-179d-worker-9rtc4-xfwkx openstudio-179d-worker-9rtc4-z9cln openstudio-179d-worker-9rtc4-zbpkv openstudio-179d-worker-9rtc4-znps8 <142 more>] [node names limited, total number of nodes: 162], error: Expected HTTP response code [202] when accessing [PUT https://vs-api.hpc.nrel.gov:9876/v2.0/lbaas/pools/d4da9983-c8f4-4c98-8e90-0676796ab9f5/members], but got 504 instead: <!DOCTYPE HTML PUBLIC "-//IETF//DTD HTML 2.0//EN">...
openstudio-server        12m         Warning   FailedPreStopHook                 pod/worker-75f95467fc-dflmr                                        PreStopHook failed
openstudio-server        12m         Normal    Killing                           pod/worker-75f95467fc-dflmr                                        Stopping container worker
openstudio-server        12m         Normal    Scheduled                         pod/worker-54568b5fb6-bxlqt                                        Successfully assigned openstudio-server/worker-54568b5fb6-bxlqt to openstudio-179d-worker-9rtc4-pqzdb
monitoring-system        12m         Normal    Pulled                            pod/loki-stack-promtail-fgrhv                                      Successfully pulled image "docker.io/grafana/promtail:2.9.3" in 4.389s (4.39s including waiting). Image size: 75094050 bytes.
calico-system            12m         Normal    SandboxChanged                    pod/csi-node-driver-zxvq2                                          Pod sandbox changed, it will be killed and re-created.
monitoring-system        12m         Normal    Started                           pod/loki-stack-promtail-fgrhv                                      Started container promtail
ingress-nginx            12m         Warning   UpdateLoadBalancerFailed          service/ingress-nginx-controller                                   Error updating load balancer with new hosts [openstudio-179d-web-tq5p9-v5jpg openstudio-179d-worker-9rtc4-2ng7h openstudio-179d-worker-9rtc4-46rwz openstudio-179d-worker-9rtc4-4hspr openstudio-179d-worker-9rtc4-6p9bz openstudio-179d-worker-9rtc4-8ltrg openstudio-179d-worker-9rtc4-8vw2k openstudio-179d-worker-9rtc4-bq8cq openstudio-179d-worker-9rtc4-cbl4x openstudio-179d-worker-9rtc4-fxpk7 openstudio-179d-worker-9rtc4-j6zt2 openstudio-179d-worker-9rtc4-r4q27 openstudio-179d-worker-9rtc4-vjtx2 openstudio-179d-worker-9rtc4-vwpvh openstudio-179d-worker-9rtc4-wf7lx openstudio-179d-worker-9rtc4-wjzm6 openstudio-179d-worker-9rtc4-xpf84 openstudio-179d-worker-9rtc4-xqpr4 openstudio-179d-worker-9rtc4-xw5d5 openstudio-179d-worker-9rtc4-zc87d <143 more>] [node names limited, total number of nodes: 163], error: Expected HTTP response code [202] when accessing [PUT https://vs-api.hpc.nrel.gov:9876/v2.0/lbaas/pools/fe769bc3-a1ec-44a2-b1ba-983a0802b93d/members], but got 500 instead: {"faultcode": "Server", "faultstring": "Unable to establish connection to https://vs-api.hpc.nlr.gov:9696/v2.0/extensions/security-group: HTTPSConnectionPool(host='vs-api.hpc.nlr.gov', port=9696): Max retries exceeded with url: /v2.0/extensions/security-group (Caused by NewConnectionError('<urllib3.connection.HTTPSConnection object at 0x7fef448da8b0>: Failed to establish a new connection: [Errno -2] Name or service not known'))", "debuginfo": null}
kube-system              12m         Normal    SandboxChanged                    pod/patch-copy-fail-txcs2                                          Pod sandbox changed, it will be killed and re-created.
kube-system              12m         Normal    Pulling                           pod/patch-copy-fail-txcs2                                          Pulling image "registry.k8s.io/e2e-test-images/busybox:1.29-2"
openstudio-server        12m         Normal    Created                           pod/web-5f9c6bbcb6-tm56n                                           Created container: init-wait-for-db
openstudio-server        12m         Normal    Pulled                            pod/web-5f9c6bbcb6-tm56n                                           Container image "registry-1.docker.io/nrel/openstudio-server:3.10.0" already present on machine
openstudio-server        12m         Normal    Scheduled                         pod/worker-54568b5fb6-kmq92                                        Successfully assigned openstudio-server/worker-54568b5fb6-kmq92 to openstudio-179d-worker-9rtc4-xh26n
openstudio-server        11m         Normal    Started                           pod/web-5f9c6bbcb6-tm56n                                           Started container web
openstudio-server        11m         Normal    Pulled                            pod/worker-54568b5fb6-kmq92                                        Container image "registry-1.docker.io/nrel/openstudio-server:3.10.0" already present on machine
openstudio-server        11m         Normal    Scheduled                         pod/worker-54568b5fb6-v74ht                                        Successfully assigned openstudio-server/worker-54568b5fb6-v74ht to openstudio-179d-worker-9rtc4-xh26n
openstudio-server        11m         Normal    Created                           pod/worker-54568b5fb6-v74ht                                        Created container: worker
openstudio-server        11m         Normal    Killing                           pod/worker-75f95467fc-58ltg                                        Stopping container worker
openstudio-server        11m         Normal    Started                           pod/worker-54568b5fb6-v74ht                                        Started container worker
openstudio-server        11m         Normal    Killing                           pod/worker-75f95467fc-m7k8r                                        Stopping container worker
openstudio-server        11m         Normal    Scheduled                         pod/worker-54568b5fb6-jxk5t                                        Successfully assigned openstudio-server/worker-54568b5fb6-jxk5t to openstudio-179d-worker-9rtc4-pqzdb
openstudio-server        11m         Normal    Pulling                           pod/worker-54568b5fb6-jxk5t                                        Pulling image "registry-1.docker.io/nrel/openstudio-server:3.10.0"
openstudio-server        11m         Normal    Pulled                            pod/worker-54568b5fb6-bxlqt                                        Successfully pulled image "registry-1.docker.io/nrel/openstudio-server:3.10.0" in 1m0.181s (1m1.711s including waiting). Image size: 1855574783 bytes.
kube-system              11m         Normal    Started                           pod/vm-max-map-count-enforcer-8k6b5                                Started container enforcer
openstudio-server        11m         Normal    Pulled                            pod/worker-54568b5fb6-jxk5t                                        Successfully pulled image "registry-1.docker.io/nrel/openstudio-server:3.10.0" in 426ms (36.2s including waiting). Image size: 1855574783 bytes.
openstudio-server        11m         Normal    Created                           pod/worker-54568b5fb6-jxk5t                                        Created container: worker
calico-system            11m         Normal    Created                           pod/csi-node-driver-zxvq2                                          Created container: csi-node-driver-registrar
calico-system            11m         Normal    Started                           pod/csi-node-driver-zxvq2                                          Started container csi-node-driver-registrar
openstudio-server        10m         Normal    Scheduled                         pod/worker-54568b5fb6-hd4vg                                        Successfully assigned openstudio-server/worker-54568b5fb6-hd4vg to openstudio-179d-worker-9rtc4-xh26n
kube-system              10m         Normal    Pulling                           pod/patch-copy-fail-txcs2                                          Pulling image "registry.k8s.io/pause:3.10.1"
openstudio-server        10m         Normal    Scheduled                         pod/worker-54568b5fb6-6jn8d                                        Successfully assigned openstudio-server/worker-54568b5fb6-6jn8d to openstudio-179d-worker-9rtc4-pqzdb
openstudio-server        10m         Warning   FailedMount                       pod/worker-54568b5fb6-hd4vg                                        MountVolume.SetUp failed for volume "kube-api-access-wdp76" : failed to fetch token: an error on the server ("<html>\r\n<head><title>502 Bad Gateway</title></head>\r\n<body>\r\n<center><h1>502 Bad Gateway</h1></center>\r\n<hr><center>nginx</center>\r\n</body>\r\n</html>") has prevented the request from succeeding (post serviceaccounts openstudio-workload)
openstudio-server        10m         Warning   FailedPreStopHook                 pod/worker-75f95467fc-99blt                                        PreStopHook failed
openstudio-server        10m         Normal    Scheduled                         pod/worker-54568b5fb6-2p88r                                        Successfully assigned openstudio-server/worker-54568b5fb6-2p88r to openstudio-179d-worker-9rtc4-pqzdb
openstudio-server        10m         Normal    Created                           pod/worker-54568b5fb6-6jn8d                                        Created container: worker
openstudio-server        10m         Normal    Killing                           pod/worker-75f95467fc-wkvz7                                        Stopping container worker
openstudio-server        10m         Normal    Pulled                            pod/worker-54568b5fb6-6jn8d                                        Container image "registry-1.docker.io/nrel/openstudio-server:3.10.0" already present on machine
openstudio-server        10m         Warning   FailedPreStopHook                 pod/worker-75f95467fc-wkvz7                                        PreStopHook failed
openstudio-server        10m         Normal    Started                           pod/worker-54568b5fb6-6jn8d                                        Started container worker
openstudio-server        10m         Normal    Pulled                            pod/worker-54568b5fb6-hd4vg                                        Container image "registry-1.docker.io/nrel/openstudio-server:3.10.0" already present on machine
openstudio-server        10m         Normal    Pulled                            pod/worker-54568b5fb6-2p88r                                        Container image "registry-1.docker.io/nrel/openstudio-server:3.10.0" already present on machine
openstudio-server        10m         Normal    Started                           pod/worker-54568b5fb6-2p88r                                        Started container worker
openstudio-server        10m         Normal    Created                           pod/worker-54568b5fb6-2p88r                                        Created container: worker
monitoring-system        10m         Warning   FailedMount                       pod/loki-stack-promtail-964st                                      MountVolume.SetUp failed for volume "kube-api-access-s8xz7" : failed to fetch token: an error on the server ("<html>\r\n<head><title>502 Bad Gateway</title></head>\r\n<body>\r\n<center><h1>502 Bad Gateway</h1></center>\r\n<hr><center>nginx</center>\r\n</body>\r\n</html>") has prevented the request from succeeding (post serviceaccounts loki-stack-promtail)
node-feature-discovery   10m         Normal    Started                           pod/node-feature-discovery-worker-vz5fq                            Started container worker
node-feature-discovery   10m         Normal    Created                           pod/node-feature-discovery-worker-vz5fq                            Created container: worker
openstudio-server        10m         Normal    Scheduled                         pod/worker-54568b5fb6-dbv52                                        Successfully assigned openstudio-server/worker-54568b5fb6-dbv52 to openstudio-179d-worker-9rtc4-pqzdb
openstudio-server        10m         Normal    Killing                           pod/worker-75f95467fc-rwwdh                                        Stopping container worker
openstudio-server        10m         Warning   FailedMount                       pod/worker-54568b5fb6-dbv52                                        MountVolume.SetUp failed for volume "kube-api-access-78g9h" : failed to fetch token: an error on the server ("<html>\r\n<head><title>502 Bad Gateway</title></head>\r\n<body>\r\n<center><h1>502 Bad Gateway</h1></center>\r\n<hr><center>nginx</center>\r\n</body>\r\n</html>") has prevented the request from succeeding (post serviceaccounts openstudio-workload)
openstudio-server        10m         Normal    Scheduled                         pod/worker-54568b5fb6-jt9b6                                        Successfully assigned openstudio-server/worker-54568b5fb6-jt9b6 to openstudio-179d-worker-9rtc4-pqzdb
openstudio-server        10m         Warning   FailedMount                       pod/worker-54568b5fb6-jt9b6                                        MountVolume.SetUp failed for volume "kube-api-access-zjpms" : failed to fetch token: an error on the server ("<html>\r\n<head><title>502 Bad Gateway</title></head>\r\n<body>\r\n<center><h1>502 Bad Gateway</h1></center>\r\n<hr><center>nginx</center>\r\n</body>\r\n</html>") has prevented the request from succeeding (post serviceaccounts openstudio-workload)
openstudio-server        10m         Normal    Started                           pod/worker-54568b5fb6-jt9b6                                        Started container worker
openstudio-server        10m         Normal    Scheduled                         pod/worker-54568b5fb6-sbsg6                                        Successfully assigned openstudio-server/worker-54568b5fb6-sbsg6 to openstudio-179d-worker-9rtc4-pqzdb
openstudio-server        10m         Normal    Scheduled                         pod/worker-54568b5fb6-66qjn                                        Successfully assigned openstudio-server/worker-54568b5fb6-66qjn to openstudio-179d-worker-9rtc4-pqzdb
openstudio-server        10m         Normal    Started                           pod/worker-54568b5fb6-dbv52                                        Started container worker
openstudio-server        10m         Normal    Created                           pod/worker-54568b5fb6-dbv52                                        Created container: worker
openstudio-server        10m         Normal    Killing                           pod/worker-75f95467fc-lxhgx                                        Stopping container worker
openstudio-server        10m         Normal    Created                           pod/worker-54568b5fb6-jt9b6                                        Created container: worker
openstudio-server        10m         Normal    Killing                           pod/worker-75f95467fc-cjvm7                                        Stopping container worker
openstudio-server        10m         Warning   FailedPreStopHook                 pod/worker-75f95467fc-lxhgx                                        PreStopHook failed
openstudio-server        10m         Normal    Started                           pod/worker-54568b5fb6-sbsg6                                        Started container worker
openstudio-server        10m         Warning   FailedPreStopHook                 pod/worker-75f95467fc-cjvm7                                        PreStopHook failed
openstudio-server        10m         Normal    Started                           pod/worker-54568b5fb6-66qjn                                        Started container worker
openstudio-server        10m         Normal    Pulled                            pod/worker-54568b5fb6-sbsg6                                        Container image "registry-1.docker.io/nrel/openstudio-server:3.10.0" already present on machine
openstudio-server        10m         Normal    Created                           pod/worker-54568b5fb6-66qjn                                        Created container: worker
openstudio-server        10m         Normal    Created                           pod/worker-54568b5fb6-sbsg6                                        Created container: worker
openstudio-server        9m52s       Normal    ScalingReplicaSet                 deployment/worker                                                  (combined from similar events): Scaled down replica set worker-75f95467fc from 454 to 453
openstudio-server        9m52s       Normal    Scheduled                         pod/worker-54568b5fb6-8rlwk                                        Successfully assigned openstudio-server/worker-54568b5fb6-8rlwk to openstudio-179d-worker-9rtc4-pqzdb
openstudio-server        9m52s       Normal    Scheduled                         pod/worker-54568b5fb6-7tmm9                                        Successfully assigned openstudio-server/worker-54568b5fb6-7tmm9 to openstudio-179d-worker-9rtc4-pqzdb
openstudio-server        9m52s       Normal    SuccessfulCreate                  replicaset/worker-54568b5fb6                                       (combined from similar events): Created pod: worker-54568b5fb6-7tmm9
openstudio-server        9m46s       Normal    Scheduled                         pod/worker-54568b5fb6-xwx9m                                        Successfully assigned openstudio-server/worker-54568b5fb6-xwx9m to openstudio-179d-worker-9rtc4-pqzdb
openstudio-server        9m46s       Normal    SuccessfulDelete                  replicaset/worker-75f95467fc                                       (combined from similar events): Deleted pod: worker-75f95467fc-29w2p
openstudio-server        9m43s       Normal    Started                           pod/worker-54568b5fb6-7tmm9                                        Started container worker
openstudio-server        9m43s       Normal    Scheduled                         pod/worker-54568b5fb6-t95fd                                        Successfully assigned openstudio-server/worker-54568b5fb6-t95fd to openstudio-179d-worker-9rtc4-964ml
openstudio-server        9m43s       Normal    Pulled                            pod/worker-54568b5fb6-7tmm9                                        Container image "registry-1.docker.io/nrel/openstudio-server:3.10.0" already present on machine
openstudio-server        9m42s       Warning   FailedMount                       pod/worker-54568b5fb6-xwx9m                                        MountVolume.SetUp failed for volume "kube-api-access-c5swd" : failed to fetch token: an error on the server ("<html>\r\n<head><title>502 Bad Gateway</title></head>\r\n<body>\r\n<center><h1>502 Bad Gateway</h1></center>\r\n<hr><center>nginx</center>\r\n</body>\r\n</html>") has prevented the request from succeeding (post serviceaccounts openstudio-workload)
openstudio-server        9m41s       Normal    Scheduled                         pod/worker-54568b5fb6-5zqmh                                        Successfully assigned openstudio-server/worker-54568b5fb6-5zqmh to openstudio-179d-worker-9rtc4-964ml
openstudio-server        9m40s       Normal    Created                           pod/worker-54568b5fb6-5zqmh                                        Created container: worker
openstudio-server        9m40s       Normal    Started                           pod/worker-54568b5fb6-5zqmh                                        Started container worker
openstudio-server        9m34s       Normal    Killing                           pod/worker-75f95467fc-c8mn6                                        Stopping container worker
openstudio-server        9m34s       Warning   FailedPreStopHook                 pod/worker-75f95467fc-c8mn6                                        PreStopHook failed
openstudio-server        9m32s       Normal    Killing                           pod/worker-75f95467fc-vzb29                                        Stopping container worker
openstudio-server        9m32s       Normal    Scheduled                         pod/worker-54568b5fb6-mjhtb                                        Successfully assigned openstudio-server/worker-54568b5fb6-mjhtb to openstudio-179d-worker-9rtc4-964ml
openstudio-server        9m31s       Normal    Started                           pod/worker-54568b5fb6-mjhtb                                        Started container worker
openstudio-server        9m31s       Normal    Pulled                            pod/worker-54568b5fb6-mjhtb                                        Container image "registry-1.docker.io/nrel/openstudio-server:3.10.0" already present on machine
openstudio-server        9m31s       Normal    Created                           pod/worker-54568b5fb6-mjhtb                                        Created container: worker
openstudio-server        9m29s       Normal    Scheduled                         pod/worker-54568b5fb6-dnjpx                                        Successfully assigned openstudio-server/worker-54568b5fb6-dnjpx to openstudio-179d-worker-9rtc4-964ml
openstudio-server        9m28s       Normal    Scheduled                         pod/worker-54568b5fb6-lk5mq                                        Successfully assigned openstudio-server/worker-54568b5fb6-lk5mq to openstudio-179d-worker-9rtc4-964ml
openstudio-server        9m28s       Warning   FailedPreStopHook                 pod/worker-75f95467fc-9swsz                                        PreStopHook failed
openstudio-server        9m20s       Normal    Created                           pod/worker-54568b5fb6-lk5mq                                        Created container: worker
kube-system              9m8s        Normal    LeaderElection                    lease/cluster-autoscaler                                           openstudio-179d-autoscaler-74d5694874-268wd became leader
openstudio-server        8m52s       Normal    Killing                           pod/worker-75f95467fc-kc7qq                                        Stopping container worker
openstudio-server        8m51s       Normal    Scheduled                         pod/worker-54568b5fb6-mjfrl                                        Successfully assigned openstudio-server/worker-54568b5fb6-mjfrl to openstudio-179d-worker-9rtc4-964ml
openstudio-server        8m51s       Warning   FailedMount                       pod/worker-54568b5fb6-mjfrl                                        MountVolume.SetUp failed for volume "kube-api-access-8n4pv" : failed to fetch token: an error on the server ("<html>\r\n<head><title>502 Bad Gateway</title></head>\r\n<body>\r\n<center><h1>502 Bad Gateway</h1></center>\r\n<hr><center>nginx</center>\r\n</body>\r\n</html>") has prevented the request from succeeding (post serviceaccounts openstudio-workload)
openstudio-server        8m50s       Normal    Started                           pod/worker-54568b5fb6-mjfrl                                        Started container worker
openstudio-server        8m50s       Normal    Created                           pod/worker-54568b5fb6-mjfrl                                        Created container: worker
openstudio-server        8m37s       Normal    Killing                           pod/worker-75f95467fc-29w2p                                        Stopping container worker
openstudio-server        8m37s       Warning   FailedPreStopHook                 pod/worker-75f95467fc-29w2p                                        PreStopHook failed
openstudio-server        8m32s       Warning   FailedPreStopHook                 pod/worker-75f95467fc-n876m                                        PreStopHook failed
openstudio-server        8m24s       Warning   FailedMount                       pod/worker-54568b5fb6-dnjpx                                        MountVolume.SetUp failed for volume "kube-api-access-rvhnz" : failed to fetch token: an error on the server ("<html>\r\n<head><title>502 Bad Gateway</title></head>\r\n<body>\r\n<center><h1>502 Bad Gateway</h1></center>\r\n<hr><center>nginx</center>\r\n</body>\r\n</html>") has prevented the request from succeeding (post serviceaccounts openstudio-workload)
openstudio-server        8m1s        Normal    Killing                           pod/worker-75f95467fc-7rjps                                        Stopping container worker
openstudio-server        6m42s       Normal    Killing                           pod/worker-75f95467fc-c5nlk                                        Stopping container worker
openstudio-server        6m41s       Warning   FailedPreStopHook                 pod/worker-75f95467fc-c5nlk                                        PreStopHook failed
kube-system              6m29s       Warning   FailedMount                       pod/vm-max-map-count-enforcer-8qqn7                                MountVolume.SetUp failed for volume "kube-api-access-tgrql" : token "default"/"kube-system"/[]string(nil)/3607/v1.BoundObjectReference{Kind:"Pod", APIVersion:"v1", Name:"vm-max-map-count-enforcer-8qqn7", UID:"d34bc3b4-1b87-4068-b10a-c65c177de20c"} expired and refresh failed: an error on the server ("<html>\r\n<head><title>502 Bad Gateway</title></head>\r\n<body>\r\n<center><h1>502 Bad Gateway</h1></center>\r\n<hr><center>nginx</center>\r\n</body>\r\n</html>") has prevented the request from succeeding (post serviceaccounts default)
kube-system              5m57s       Warning   FailedMount                       pod/patch-copy-fail-wv5bt                                          MountVolume.SetUp failed for volume "kube-api-access-xt8wx" : failed to fetch token: an error on the server ("<html>\r\n<head><title>502 Bad Gateway</title></head>\r\n<body>\r\n<center><h1>502 Bad Gateway</h1></center>\r\n<hr><center>nginx</center>\r\n</body>\r\n</html>") has prevented the request from succeeding (post serviceaccounts default)
openstudio-server        5m7s        Warning   LoadBalancerSourceRangesIgnored   service/ingress-load-balancer                                      LoadBalancerSourceRanges are ignored for Service openstudio-server/ingress-load-balancer because Octavia provider does not support it
openstudio-server        5m7s        Normal    EnsuringLoadBalancer              service/ingress-load-balancer                                      Ensuring load balancer
openstudio-server        4m3s        Warning   SyncLoadBalancerFailed            service/ingress-load-balancer                                      Error syncing load balancer: failed to ensure load balancer: Put "https://vs-api.hpc.nrel.gov:9876/v2.0/lbaas/pools/d4da9983-c8f4-4c98-8e90-0676796ab9f5/members": context deadline exceeded (Client.Timeout exceeded while awaiting headers)
openstudio-server        4m          Warning   FailedGetResourceMetric           horizontalpodautoscaler/web                                        failed to get cpu utilization: unable to get metrics for resource cpu: no metrics returned from resource metrics API
openstudio-server        4m          Warning   FailedComputeMetricsReplicas      horizontalpodautoscaler/web                                        invalid metrics (1 invalid out of 1), first error is: failed to get cpu resource metric value: failed to get cpu utilization: unable to get metrics for resource cpu: no metrics returned from resource metrics API
ingress-nginx            3m59s       Normal    EnsuringLoadBalancer              service/ingress-nginx-controller                                   Ensuring load balancer
ingress-nginx            3m59s       Warning   LoadBalancerSourceRangesIgnored   service/ingress-nginx-controller                                   LoadBalancerSourceRanges are ignored for Service ingress-nginx/ingress-nginx-controller because Octavia provider does not support it
ingress-nginx            3m54s       Warning   SyncLoadBalancerFailed            service/ingress-nginx-controller                                   (combined from similar events): Error syncing load balancer: failed to ensure load balancer: Expected HTTP response code [202] when accessing [PUT https://vs-api.hpc.nrel.gov:9876/v2.0/lbaas/pools/fe769bc3-a1ec-44a2-b1ba-983a0802b93d/members], but got 500 instead: {"faultcode": "Server", "faultstring": "Unable to establish connection to https://vs-api.hpc.nlr.gov:9696/v2.0/extensions/security-group: HTTPSConnectionPool(host='vs-api.hpc.nlr.gov', port=9696): Max retries exceeded with url: /v2.0/extensions/security-group (Caused by NewConnectionError('<urllib3.connection.HTTPSConnection object at 0x7f5461561880>: Failed to establish a new connection: [Errno -2] Name or service not known'))", "debuginfo": null}
openstudio-server        3m34s       Warning   FailedMount                       pod/worker-75f95467fc-h9ghv                                        MountVolume.SetUp failed for volume "kube-api-access-ccj6g" : token "openstudio-workload"/"openstudio-server"/[]string(nil)/3607/v1.BoundObjectReference{Kind:"Pod", APIVersion:"v1", Name:"worker-75f95467fc-h9ghv", UID:"f8f7291d-52b5-424d-8700-26a6abac0403"} expired and refresh failed: an error on the server ("<html>\r\n<head><title>502 Bad Gateway</title></head>\r\n<body>\r\n<center><h1>502 Bad Gateway</h1></center>\r\n<hr><center>nginx</center>\r\n</body>\r\n</html>") has prevented the request from succeeding (post serviceaccounts openstudio-workload)
openstudio-server        3m22s       Warning   FailedMount                       pod/worker-75f95467fc-ptv8c                                        MountVolume.SetUp failed for volume "kube-api-access-cjkvb" : token "openstudio-workload"/"openstudio-server"/[]string(nil)/3607/v1.BoundObjectReference{Kind:"Pod", APIVersion:"v1", Name:"worker-75f95467fc-ptv8c", UID:"e329519d-bef5-433a-a4ee-bb86ae3cd044"} expired and refresh failed: an error on the server ("<html>\r\n<head><title>502 Bad Gateway</title></head>\r\n<body>\r\n<center><h1>502 Bad Gateway</h1></center>\r\n<hr><center>nginx</center>\r\n</body>\r\n</html>") has prevented the request from succeeding (post serviceaccounts openstudio-workload)
openstudio-server        3m2s        Warning   FailedMount                       pod/worker-75f95467fc-qgt5t                                        MountVolume.SetUp failed for volume "kube-api-access-mn4lr" : failed to fetch token: an error on the server ("<html>\r\n<head><title>502 Bad Gateway</title></head>\r\n<body>\r\n<center><h1>502 Bad Gateway</h1></center>\r\n<hr><center>nginx</center>\r\n</body>\r\n</html>") has prevented the request from succeeding (post serviceaccounts openstudio-workload)
openstudio-server        2m53s       Warning   FailedScheduling                  pod/worker-54568b5fb6-p7cv2                                        0/166 nodes are available: 160 Insufficient memory, 3 node(s) had untolerated taint {node-role.kubernetes.io/control-plane: }, 8 Insufficient cpu. preemption: 0/166 nodes are available: 163 No preemption victims found for incoming pod, 3 Preemption is not helpful for scheduling.
openstudio-server        2m50s       Warning   FailedMount                       pod/worker-75f95467fc-7r8pb                                        MountVolume.SetUp failed for volume "kube-api-access-7r2rn" : failed to fetch token: an error on the server ("<html>\r\n<head><title>502 Bad Gateway</title></head>\r\n<body>\r\n<center><h1>502 Bad Gateway</h1></center>\r\n<hr><center>nginx</center>\r\n</body>\r\n</html>") has prevented the request from succeeding (post serviceaccounts openstudio-workload)
kube-system              2m38s       Normal    LeaderElection                    lease/cluster-autoscaler                                           openstudio-179d-autoscaler-74d5694874-268wd became leader
default                  2m11s       Warning   FailedGetScale                    horizontalpodautoscaler/worker                                     deployments.apps "worker" not found
openstack-system         90s         Warning   FailedMount                       pod/openstack-cinder-csi-nodeplugin-fdw59                          MountVolume.SetUp failed for volume "kube-api-access-kz649" : token "csi-cinder-node-sa"/"openstack-system"/[]string(nil)/3607/v1.BoundObjectReference{Kind:"Pod", APIVersion:"v1", Name:"openstack-cinder-csi-nodeplugin-fdw59", UID:"9dc0bc07-a783-4489-b9d3-b0e3bf2e4752"} expired and refresh failed: an error on the server ("<html>\r\n<head><title>502 Bad Gateway</title></head>\r\n<body>\r\n<center><h1>502 Bad Gateway</h1></center>\r\n<hr><center>nginx</center>\r\n</body>\r\n</html>") has prevented the request from succeeding (post serviceaccounts csi-cinder-node-sa)
openstudio-server        83s         Warning   FailedScheduling                  pod/worker-54568b5fb6-5xw8p                                        0/166 nodes are available: 160 Insufficient memory, 3 node(s) had untolerated taint {node-role.kubernetes.io/control-plane: }, 8 Insufficient cpu. preemption: 0/166 nodes are available: 163 No preemption victims found for incoming pod, 3 Preemption is not helpful for scheduling.
